Workbook

Sheet Assumptions
A1: Assumptions
A4: Block 1: Per-vehicle activity and energy intensity
A5: Vehicle category | B5: Annual VKT (km/yr) | C5: Energy intensity (kWh/km) | D5: Home-charge share | E5: Use battery swap? | F5: Source / Notes
A6: Motorcycle | B6: =D6*B88+(1-D6)*B89 -> 16296 | C6: 0.03 | D6: 0.5 | E6: YES: Class VKT = home (private-duty) share x private VKT + commercial share x commercial VKT (Block 14). | F6: VKT: SSA boda-boda/okada studies; kWh/km: Average valude from Indonesia Electric Motorcycle Roadmap [https://www.adb.org/sites/default/files/publication/830831/electric-motorcycle-charging-infrastructure-indonesia.pdf]
A7: Private car | B7: 32500 | C7: 0.17 | D7: 0.4 | E7: No | F7: VKT: Cervigni 2013 Ch.21 [https://documents1.worldbank.org/curated/en/333931468332952975/pdf/Assessing-low-carbon-development-in-Nigeria-an-analysis-of-four-sectors.pdf]; kWh/km: Hypercharge [https://hypercharge.com/blog/how-fuel-efficient-are-evs-cost-per-distance-to-drive-electric/]
A8: Light commercial | B8: 20600 | C8: 0.22 | D8: 0.3 | E8: No | F8: VKT: light freight benchmarks [https://www.sciencedirect.com/science/article/abs/pii/S2352550923000635; https://documents1.worldbank.org/curated/en/333931468332952975/pdf/Assessing-low-carbon-development-in-Nigeria-an-analysis-of-four-sectors.pdf]; kWh/km: Our assumption LCV energy intensity of 0.22 kWh/km is consistent with U.S. DOE/EPA EV efficiency benchmarks. The U.S. DOE reports that light-duty all-electric vehicles can consume roughly 25–40 kWh per 100 miles; 0.22 kWh/km converts to about 35.4 kWh/100 miles, which falls within this range [https://afdc.energy.gov/fuels/electricity-benefits]
A9: Heavy goods | B9: 33700 | C9: 1.3 | D9: 0 | E9: No | F9: Heavy-truck Nigeria avg [https://documents1.worldbank.org/curated/en/333931468332952975/pdf/Assessing-low-carbon-development-in-Nigeria-an-analysis-of-four-sectors.pdf]; kWh/km: Designwerk [https://www.designwerk.com/en/post/e-truck/from-real-operation-consumption-values-of-electric-trucks-in-special-applications/]
A10: Light bus | B10: 21400 | C10: 0.7 | D10: 0 | E10: No | F10: The IEA assumes electric minibuses consume 0.35–1.49 kWh/km and our assumption falls within [https://www.iea.org/data-and-statistics/charts/electricity-demand-from-the-electric-vehicle-fleet-by-country-and-region-2030]
A11: Coach | B11: 33200 | C11: 1.5 | D11: 0 | E11: No | F11: Intercity coach activity factors [https://documents1.worldbank.org/curated/en/333931468332952975/pdf/Assessing-low-carbon-development-in-Nigeria-an-analysis-of-four-sectors.pdf]; kWh/km: Alarrouqi et al [https://www.sciencedirect.com/science/article/pii/S235246772400081X]
A14: Block 2: EV adoption S-curve parameters
A15: Vehicle category | B15: t50 (year EV share = 50%) | C15: k (steepness) | F15: Rationale
A16: Motorcycle | B16: 2046.1 | C16: 0.279 | F16: Earliest electrification (Ampersand model already proven in East Africa)
A17: Private car | B17: 2048.4 | C17: 0.254 | F17: Tracks Nigeria ETP middle-of-road
A18: Light commercial | B18: 2049.1 | C18: 0.224 | F18: Commercial fleets follow private LDV with slight lag
A19: Heavy goods | B19: 2053.1 | C19: 0.201 | F19: Most CAPEX-intensive segment; longest payback
A20: Light bus | B20: 2047.3 | C20: 0.233 | F20: Urban fleets electrify early under air-quality mandates
A21: Coach | B21: 2050 | C21: 0.22 | F21: Intercity routes require fast/depot charging; intermediate timing
A24: Block 3: Charger-to-EV ratios
A25: Charger type | B25: EVs per charger
A26: Home L2 | B26: 1.2
A27: Public AC | B27: 12
A28: Public DC fast | B28: 60
A29: Depot HD | B29: 2.5
A30: Swap station (motorcycles per station) | B30: 250
A33: Block 4: Charger CAPEX (USD per port, all-in incl. installation)
A34: Charger type | B34: CAPEX USD/port | C34: Rated power (kW) | D34: Diversity factor
A35: Home L2 | B35: 1500 | C35: 7.4 | D35: 0.2
A36: Public AC | B36: 5500 | C36: 22 | D36: 0.3
A37: Public DC fast | B37: 55000 | C37: 100 | D37: 0.4
A38: Depot HD | B38: 85000 | C38: 250 | D38: 0.6
A39: Swap station | B39: 350000 | C39: 200 | D39: 0.5
A42: Block 5: Grid upgrade unit cost
A43: Grid upgrade USD per kW of new EV peak load | B43: 450
A45: Block 6: Macro inputs (population and GDP_pc for context; not directly used in charging calcs)
A46: Nigeria 2024 GDP/capita (constant 2015 US$; WDI GDP / WPP 2024 population) | B46: ='GDP and Population'!B19 -> 2348.9093 | F46: World Bank [https://data.worldbank.org/indicator/NY.GDP.PCAP.PP.CD?locations=NG]
A47: Assumed real GDP/capita growth, 2024-2060 (CAGR) | B47: 0.025 | F47: Moderate convergence; sensitivity-tested
A48: Nigeria 2060 population (M; UN WPP 2024 medium, 1 January) | B48: ='GDP and Population'!D55 -> 397.91185 | F48: UN DESA WPP [https://population.un.org/wpp/]
A50: Block 7: Level 1 (Mode 2 socket) home charging
A51: Level 1 share of LDV home charging | B51: 0.7 | C51: Share of car/LCV home charging done on a standard 230 V socket (Level 1, Mode 2) rather than a dedicated 7 kW Level 2 unit. IEA GEVO 2024: socket charging is the most common home mode in 220-240 V grids.
A52: EVs per Level 1 socket | B52: 1 | C52: One socket per home-charging vehicle.
...

Sheet GDP and Population
A1: GDP per capita (constant 2015 US$) and population, Nigeria 2010 to 2060
A2: GDP per capita (constant 2015 US$) = World Bank WDI GDP divided by UN WPP 2024 population; population to 2060 = UN WPP 2024 medium variant
A4: Year | B4: GDP/cap (constant 2015 US$) | C4: GDP (constant 2015 US$) | D4: Population (M) | E4: GDP/cap growth (yoy) | F4: Pop growth (yoy)
A5: 2010 | B5: =C5/(D5*1000000) -> 2348.4232 | C5: 3.8585606e+11 | D5: 164.30431
A6: 2011 | B6: =C6/(D6*1000000) -> 2404.6249 | C6: 4.0633701e+11 | D6: 168.98146 | E6: =B6/B5-1 -> 0.023931652 | F6: =D6/D5-1 -> 0.028466343
A7: 2012 | B7: =C7/(D7*1000000) -> 2437.1667 | C7: 4.2352532e+11 | D7: 173.77774 | E7: =B7/B6-1 -> 0.013533022 | F7: =D7/D6-1 -> 0.028383475
A8: 2013 | B8: =C8/(D8*1000000) -> 2529.2309 | C8: 4.5178011e+11 | D8: 178.62351 | E8: =B8/B7-1 -> 0.03777511 | F8: =D8/D7-1 -> 0.027884889
A9: 2014 | B9: =C9/(D9*1000000) -> 2617.7146 | C9: 4.8028616e+11 | D9: 183.47538 | E9: =B9/B8-1 -> 0.034984406 | F9: =D9/D8-1 -> 0.027162516
A10: 2015 | B10: =C10/(D10*1000000) -> 2618.0476 | C10: 4.9302668e+11 | D10: 188.31846 | E10: =B10/B9-1 -> 0.00012722583 | F10: =D10/D9-1 -> 0.026396349
A11: 2016 | B11: =C11/(D11*1000000) -> 2512.9094 | C11: 4.8505509e+11 | D11: 193.0253 | E11: =B11/B10-1 -> -0.040159029 | F11: =D11/D10-1 -> 0.024994077
A12: 2017 | B12: =C12/(D12*1000000) -> 2471.2367 | C12: 4.8896408e+11 | D12: 197.8621 | E12: =B12/B11-1 -> -0.016583433 | F12: =D12/D11-1 -> 0.025057845
A13: 2018 | B13: =C13/(D13*1000000) -> 2459.2791 | C13: 4.9836567e+11 | D13: 202.64706 | E13: =B13/B12-1 -> -0.0048387131 | F13: =D13/D12-1 -> 0.024183303
A14: 2019 | B14: =C14/(D14*1000000) -> 2457.9965 | C14: 5.0937173e+11 | D14: 207.23045 | E14: =B14/B13-1 -> -0.00052152586 | F14: =D14/D13-1 -> 0.022617614
A15: 2020 | B15: =C15/(D15*1000000) -> 2252.4251 | C15: 4.7693036e+11 | D15: 211.74083 | E15: =B15/B14-1 -> -0.083633737 | F15: =D15/D14-1 -> 0.021765045
A16: 2021 | B16: =C16/(D16*1000000) -> 2229.9066 | C16: 4.8222072e+11 | D16: 216.25153 | E16: =B16/B15-1 -> -0.0099974296 | F16: =D16/D15-1 -> 0.02130293
A17: 2022 | B17: =C17/(D17*1000000) -> 2278.22 | C17: 5.0304701e+11 | D17: 220.80704 | E17: =B17/B16-1 -> 0.021666084 | F17: =D17/D16-1 -> 0.021065798
... A19: 2024 | B19: =C19/(D19*1000000) -> 2348.9093 | C19: 5.4088602e+11 | D19: 230.27114 | E19: =B19/B18-1 -> 0.019123756 | F19: =D19/D18-1 -> 0.021181832
A20: 2025 | B20: =B19*(1+Assumptions!$B$47) -> 2407.632 | D20: 235.08781 | E20: =B20/B19-1 -> 0.025 | F20: =D20/D19-1 -> 0.020917398
A21: 2026 | B21: =B20*(1+Assumptions!$B$47) -> 2467.8228 | D21: 239.96775 | E21: =B21/B20-1 -> 0.025 | F21: =D21/D20-1 -> 0.020757924
A22: 2027 | B22: =B21*(1+Assumptions!$B$47) -> 2529.5184 | D22: 244.89592 | E22: =B22/B21-1 -> 0.025 | F22: =D22/D21-1 -> 0.020536785
A23: 2028 | B23: =B22*(1+Assumptions!$B$47) -> 2592.7564 | D23: 249.85261 | E23: =B23/B22-1 -> 0.025 | F23: =D23/D22-1 -> 0.020240007
A24: 2029 | B24: =B23*(1+Assumptions!$B$47) -> 2657.5753 | D24: 254.83964 | E24: =B24/B23-1 -> 0.025 | F24: =D24/D23-1 -> 0.019959908
A25: 2030 | B25: =B24*(1+Assumptions!$B$47) -> 2724.0146 | D25: 259.86563 | E25: =B25/B24-1 -> 0.025 | F25: =D25/D24-1 -> 0.019722151
A26: 2031 | B26: =B25*(1+Assumptions!$B$47) -> 2792.115 | D26: 264.89631 | E26: =B26/B25-1 -> 0.025 | F26: =D26/D25-1 -> 0.019358762
A27: 2032 | B27: =B26*(1+Assumptions!$B$47) -> 2861.9179 | D27: 269.94584 | E27: =B27/B26-1 -> 0.025 | F27: =D27/D26-1 -> 0.0190623
A28: 2033 | B28: =B27*(1+Assumptions!$B$47) -> 2933.4658 | D28: 275.02144 | E28: =B28/B27-1 -> 0.025 | F28: =D28/D27-1 -> 0.018802297
A29: 2034 | B29: =B28*(1+Assumptions!$B$47) -> 3006.8025 | D29: 280.08879 | E29: =B29/B28-1 -> 0.025 | F29: =D29/D28-1 -> 0.018425269
A30: 2035 | B30: =B29*(1+Assumptions!$B$47) -> 3081.9725 | D30: 285.15601 | E30: =B30/B29-1 -> 0.025 | F30: =D30/D29-1 -> 0.018091478
A31: 2036 | B31: =B30*(1+Assumptions!$B$47) -> 3159.0219 | D31: 290.21552 | E31: =B31/B30-1 -> 0.025 | F31: =D31/D30-1 -> 0.017742958
... A55: 2060 | B55: =B54*(1+Assumptions!$B$47) -> 5713.8048 | D55: 397.91185 | E55: =B55/B54-1 -> 0.025 | F55: =D55/D54-1 -> 0.0096546472

Sheet Gompertz fit
A1: Gompertz fit of Nigerian vehicle ownership vs GDP per capita (one estimated 2010 anchor and two observed NBS counts)
A3: Inputs
A12: gamma (saturation ceiling, vehicles per 1,000 persons): | B12: 300 | C12: Dargay, Gately & Sommer (2007) high-income asymptote 850 (652 cars); South Africa ~176, Morocco ~112 today. 300 is an intermediate ceiling; sensitivity 225-375 (+/-25%).
A14: Anchor data (2010: World Bank base-year estimate; 2017 and 2018: observed NBS counts)
A15: Year | B15: Vehicle stock (M) | C15: Population (M) | D15: GDP/cap (const. 2015 US$) | E15: V/P (per 1000) | F15: V/(P*gamma) | G15: LN(V/(P*gamma)) | H15: y_lin = LN(-LN(V/(P*gamma)))
A16: 2010 | B16: 8.671474 | C16: ='GDP and Population'!D5 -> 164.30431 | D16: ='GDP and Population'!B5 -> 2348.4232 | E16: =B16*1000/C16 -> 52.77691 | F16: =E16/$B$12 -> 0.17592303 | G16: =LN(F16) -> -1.7377087 | H16: =LN(-G16) -> 0.5525674 | I16: World Bank Cervigni et al. (2013) Table 22.4 base year (SLA 2005 uplifted)
A17: 2017 | B17: 11.45837 | C17: ='GDP and Population'!D12 -> 197.8621 | D17: ='GDP and Population'!B12 -> 2471.2367 | E17: =B17*1000/C17 -> 57.910889 | F17: =E17/$B$12 -> 0.1930363 | G17: =LN(F17) -> -1.644877 | H17: =LN(-G17) -> 0.49766564 | I17: NBS Road Transport Data Q1 2017 (vehicle population)
A18: 2018 | B18: 11.826033 | C18: ='GDP and Population'!D13 -> 202.64706 | D18: ='GDP and Population'!B13 -> 2459.2791 | E18: =B18*1000/C18 -> 58.357783 | F18: =E18/$B$12 -> 0.19452594 | G18: =LN(F18) -> -1.6371897 | H18: =LN(-G18) -> 0.4929812 | I18: NBS Road Transport Data Q4 2018 (vehicle population; last official total)
A20: Linearised regression (LINEST with statistics)
A21: Slope (= beta): | B21: =INDEX(LINEST(H16:H18,D16:D18,TRUE(),TRUE()),1,1) -> -0.00048308424
A22: Intercept (= LN(-alpha)): | B22: =INDEX(LINEST(H16:H18,D16:D18,TRUE(),TRUE()),1,2) -> 1.6865183
A23: SE of slope: | B23: =STEYX(H16:H18,D16:D18)/SQRT(DEVSQ(D16:D18)) -> 7.754087e-05
A24: Fitted alpha (= -EXP(intercept)): | B24: =-EXP(B22) -> -5.4006446
A25: Fitted beta (= slope): | B25: =B21 -> -0.00048308424
A26: R^2 (linearised): | B26: =INDEX(LINEST(H16:H18,D16:D18,TRUE(),TRUE()),3,1) -> 0.97488298
A27: SE of intercept: | B27: =INDEX(LINEST(H16:H18,D16:D18,TRUE(),TRUE()),2,2) -> 0.18818727
A28: Degrees of freedom: | B28: =INDEX(LINEST(H16:H18,D16:D18,TRUE(),TRUE()),4,2) -> 1
A29: t-statistic (beta): | B29: =B21/B23 -> -6.2300596
A30: 95% CI beta (lower, upper): | B30: =B21-TINV(0.05,B28)*B23 -> -0.0014683344 | C30: =B21+TINV(0.05,B28)*B23 -> 0.00050216593
A32: With three anchors (one estimated, two observed) and two parameters there is one degree of freedom; the parameters are weakly identified and confidence intervals are wide. We therefore treat the saturation ceiling gamma as the primary uncertainty (225-375 sensitivity) rather than relying on the statistical precision of alpha and beta.
A34: Fit quality at anchor years
A35: Year | B35: Actual V/1000 | C35: Predicted V/1000 | D35: Residual | E35: % error
A36: =A16 -> 2010 | B36: =E16 -> 52.77691 | C36: =$B$12*EXP($B$24*EXP($B$25*D16)) -> 52.826015 | D36: =B36-C36 -> -0.049104456 | E36: =D36/B36 -> -0.00093041553
A37: =A17 -> 2017 | B37: =E17 -> 57.910889 | C37: =$B$12*EXP($B$24*EXP($B$25*D17)) -> 58.384383 | D37: =B37-C37 -> -0.47349424 | E37: =D37/B37 -> -0.0081762559
A38: =A18 -> 2018 | B38: =E18 -> 58.357783 | C38: =$B$12*EXP($B$24*EXP($B$25*D18)) -> 57.833398 | D38: =B38-C38 -> 0.52438448 | E38: =D38/B38 -> 0.008985682

Sheet Fleet projections
A1: Annual fleet projections 2010 to 2060, anchored on the 2010 base-year estimate and observed NBS counts
A2: Phase 1 (2010-2018): geometric interpolation between the anchors (WB base-year 2010 estimate; observed NBS counts 2017, 2018). Bridge (2019-2024): anchor-derived 2010-2018 CAGR (NBS discontinued the vehicle-population series after Q4 2018). Phase 2 (2025-2060): Scenario A = constant CAGR at the World Bank 2013-implied 2010-2035 rate (upper bound); Scenario B = Gompertz (gamma = 300) fitted to observed anchors and driven by GDP/cap and population (central); Scenario C = CAGR declining linearly from the observed rate to a terminal rate equal to population growth plus income-elasticity x GDP/cap growth (lower bound). The World Bank 2013 projection is shown for comparison only.
A4: Vehicle-stock anchors (2010 estimate; 2017 and 2018 observed NBS counts)
A5: Year | B5: Total fleet (M) | C5: Source
A6: 2010 | B6: 8.671474 | C6: World Bank Cervigni et al. (2013) Table 22.4 base year
A7: 2017 | B7: 11.45837 | C7: NBS Road Transport Data Q1 2017 (vehicle population)
A8: 2018 | B8: 11.826033 | C8: NBS Road Transport Data Q4 2018 (vehicle population; last official total)
A10: Growth-rate parameters
A11: Anchor-derived CAGR 2010-2018: | B11: =(B8/B6)^(1/8)-1 -> 0.039544943
A12: Scenario A CAGR (WB 2013-implied 2010-2035): | B12: =(44.79147/8.671474)^(1/25)-1 -> 0.067884039 | C12: Cervigni et al. (2013) Table 22.4: 8.671M (2010) to 44.791M (2035). Editable.
A13: Scenario C starting CAGR (2025): | B13: =B11 -> 0.039544943
A14: Scenario C terminal CAGR (2060): | B14: =('GDP and Population'!D55/'GDP and Population'!D54-1)+Assumptions!$B$85*Assumptions!$B$47 -> 0.032154647 | C14: Population growth 2059-60 (UN WPP 2024) + income elasticity (Assumptions B85) x real GDP/cap growth (Assumptions B47).
A15: Scenario B anchor scaling factor (bridged 2024 fleet / Gompertz fit at 2024): | B15: =D32/(H32*G32/1000) -> 1.226406
A16: Annual projections (vehicles, millions)
A17: Year | B17: Anchored (2010-2018) / bridged (2019-2024) (M) | C17: Scenario A (upper) | D17: Scenario B (central, Gompertz) | E17: Scenario C (lower) | F17: B: GDP/cap | G17: B: Population (M) | H17: B: V/1000 | I17: C: CAGR this year | J17: WB 2013 projection (M)
A18: 2010 | B18: =$B$6 -> 8.671474 | C18: =B18 -> 8.671474 | D18: =B18 -> 8.671474 | E18: =B18 -> 8.671474 | F18: ='GDP and Population'!B5 -> 2348.4232 | G18: ='GDP and Population'!D5 -> 164.30431 | H18: ='Gompertz fit'!$B$12*EXP('Gompertz fit'!$B$24*EXP('Gompertz fit'!$B$25*F18)) -> 52.826015 | J18: 8.671474
A19: 2011 | B19: =$B$6*($B$7/$B$6)^(0.142857) -> 9.0236636 | C19: =B19 -> 9.0236636 | D19: =B19 -> 9.0236636 | E19: =B19 -> 9.0236636 | F19: ='GDP and Population'!B6 -> 2404.6249 | G19: ='GDP and Population'!D6 -> 168.98146 | H19: ='Gompertz fit'!$B$12*EXP('Gompertz fit'!$B$24*EXP('Gompertz fit'!$B$25*F19)) -> 55.341505 | J19: 9.3101
A20: 2012 | B20: =$B$6*($B$7/$B$6)^(0.285714) -> 9.3901573 | C20: =B20 -> 9.3901573 | D20: =B20 -> 9.3901573 | E20: =B20 -> 9.3901573 | F20: ='GDP and Population'!B7 -> 2437.1667 | G20: ='GDP and Population'!D7 -> 173.77774 | H20: ='Gompertz fit'!$B$12*EXP('Gompertz fit'!$B$24*EXP('Gompertz fit'!$B$25*F20)) -> 56.819924 | J20: 9.9957
A21: 2013 | B21: =$B$6*($B$7/$B$6)^(0.428571) -> 9.771536 | C21: =B21 -> 9.771536 | D21: =B21 -> 9.771536 | E21: =B21 -> 9.771536 | F21: ='GDP and Population'!B8 -> 2529.2309 | G21: ='GDP and Population'!D8 -> 178.62351 | H21: ='Gompertz fit'!$B$12*EXP('Gompertz fit'!$B$24*EXP('Gompertz fit'!$B$25*F21)) -> 61.085038 | J21: 10.7318
A22: 2014 | B22: =$B$6*($B$7/$B$6)^(0.571429) -> 10.168407 | C22: =B22 -> 10.168407 | D22: =B22 -> 10.168407 | E22: =B22 -> 10.168407 | F22: ='GDP and Population'!B9 -> 2617.7146 | G22: ='GDP and Population'!D9 -> 183.47538 | H22: ='Gompertz fit'!$B$12*EXP('Gompertz fit'!$B$24*EXP('Gompertz fit'!$B$25*F22)) -> 65.291569 | J22: 11.5221
A23: 2015 | B23: =$B$6*($B$7/$B$6)^(0.714286) -> 10.581394 | C23: =B23 -> 10.581394 | D23: =B23 -> 10.581394 | E23: =B23 -> 10.581394 | F23: ='GDP and Population'!B10 -> 2618.0476 | G23: ='GDP and Population'!D10 -> 188.31846 | H23: ='Gompertz fit'!$B$12*EXP('Gompertz fit'!$B$24*EXP('Gompertz fit'!$B$25*F23)) -> 65.307588 | J23: 12.3706
A24: 2016 | B24: =$B$6*($B$7/$B$6)^(0.857143) -> 11.011155 | C24: =B24 -> 11.011155 | D24: =B24 -> 11.011155 | E24: =B24 -> 11.011155 | F24: ='GDP and Population'!B11 -> 2512.9094 | G24: ='GDP and Population'!D11 -> 193.0253 | H24: ='Gompertz fit'!$B$12*EXP('Gompertz fit'!$B$24*EXP('Gompertz fit'!$B$25*F24)) -> 60.320303 | J24: 13.2816
A25: 2017 | B25: =$B$7 -> 11.45837 | C25: =B25 -> 11.45837 | D25: =B25 -> 11.45837 | E25: =B25 -> 11.45837 | F25: ='GDP and Population'!B12 -> 2471.2367 | G25: ='GDP and Population'!D12 -> 197.8621 | H25: ='Gompertz fit'!$B$12*EXP('Gompertz fit'!$B$24*EXP('Gompertz fit'!$B$25*F25)) -> 58.384383 | J25: 14.2596
A26: 2018 | B26: =$B$8 -> 11.826033 | C26: =B26 -> 11.826033 | D26: =B26 -> 11.826033 | E26: =B26 -> 11.826033 | F26: ='GDP and Population'!B13 -> 2459.2791 | G26: ='GDP and Population'!D13 -> 202.64706 | H26: ='Gompertz fit'!$B$12*EXP('Gompertz fit'!$B$24*EXP('Gompertz fit'!$B$25*F26)) -> 57.833398 | J26: 15.3098
A27: 2019 | B27: =B26*(1+$B$11) -> 12.293693 | C27: =B27 -> 12.293693 | D27: =B27 -> 12.293693 | E27: =B27 -> 12.293693 | F27: ='GDP and Population'!B14 -> 2457.9965 | G27: ='GDP and Population'!D14 -> 207.23045 | H27: ='Gompertz fit'!$B$12*EXP('Gompertz fit'!$B$24*EXP('Gompertz fit'!$B$25*F27)) -> 57.774421 | J27: 16.4372
A28: 2020 | B28: =B27*(1+$B$11) -> 12.779846 | C28: =B28 -> 12.779846 | D28: =B28 -> 12.779846 | E28: =B28 -> 12.779846 | F28: ='GDP and Population'!B15 -> 2252.4251 | G28: ='GDP and Population'!D15 -> 211.74083 | H28: ='Gompertz fit'!$B$12*EXP('Gompertz fit'!$B$24*EXP('Gompertz fit'!$B$25*F28)) -> 48.645705 | J28: 17.647653
A29: 2021 | B29: =B28*(1+$B$11) -> 13.285224 | C29: =B29 -> 13.285224 | D29: =B29 -> 13.285224 | E29: =B29 -> 13.285224 | F29: ='GDP and Population'!B16 -> 2229.9066 | G29: ='GDP and Population'!D16 -> 216.25153 | H29: ='Gompertz fit'!$B$12*EXP('Gompertz fit'!$B$24*EXP('Gompertz fit'!$B$25*F29)) -> 47.687317 | J29: 18.8382
A30: 2022 | B30: =B29*(1+$B$11) -> 13.810588 | C30: =B30 -> 13.810588 | D30: =B30 -> 13.810588 | E30: =B30 -> 13.810588 | F30: ='GDP and Population'!B17 -> 2278.22 | G30: ='GDP and Population'!D17 -> 220.80704 | H30: ='Gompertz fit'!$B$12*EXP('Gompertz fit'!$B$24*EXP('Gompertz fit'!$B$25*F30)) -> 49.754074 | J30: 20.109
A31: 2023 | B31: =B30*(1+$B$11) -> 14.356727 | C31: =B31 -> 14.356727 | D31: =B31 -> 14.356727 | E31: =B31 -> 14.356727 | F31: ='GDP and Population'!B18 -> 2304.8322 | G31: ='GDP and Population'!D18 -> 225.49475 | H31: ='Gompertz fit'!$B$12*EXP('Gompertz fit'!$B$24*EXP('Gompertz fit'!$B$25*F31)) -> 50.909151 | J31: 21.4656
A32: 2024 | B32: =B31*(1+$B$11) -> 14.924463 | C32: =B32 -> 14.924463 | D32: =B32 -> 14.924463 | E32: =B32 -> 14.924463 | F32: ='GDP and Population'!B19 -> 2348.9093 | G32: ='GDP and Population'!D19 -> 230.27114 | H32: ='Gompertz fit'!$B$12*EXP('Gompertz fit'!$B$24*EXP('Gompertz fit'!$B$25*F32)) -> 52.84756 | J32: 22.9137
A33: 2025 | C33: =C32*(1+$B$12) -> 15.937596 | D33: =$D$32*(H33*G33)/($H$32*$G$32) -> 15.994879 | E33: =E32*(1+I33) -> 15.511586 | F33: ='GDP and Population'!B20 -> 2407.632 | G33: ='GDP and Population'!D20 -> 235.08781 | H33: ='Gompertz fit'!$B$12*EXP('Gompertz fit'!$B$24*EXP('Gompertz fit'!$B$25*F33)) -> 55.477462 | I33: =$B$13+(0.027778)*($B$14-$B$13) -> 0.039339655 | J33: 24.4595
A34: 2026 | C34: =C33*(1+$B$12) -> 17.019504 | D34: =$D$32*(H34*G34)/($H$32*$G$32) -> 17.136044 | E34: =E33*(1+I34) -> 16.118622 | F34: ='GDP and Population'!B21 -> 2467.8228 | G34: ='GDP and Population'!D21 -> 239.96775 | H34: ='Gompertz fit'!$B$12*EXP('Gompertz fit'!$B$24*EXP('Gompertz fit'!$B$25*F34)) -> 58.226869 | I34: =$B$13+(0.055556)*($B$14-$B$13) -> 0.039134368 | J34: 26.1096
A35: 2027 | C35: =C34*(1+$B$12) -> 18.174857 | D35: =$D$32*(H35*G35)/($H$32*$G$32) -> 18.350446 | E35: =E34*(1+I35) -> 16.746105 | F35: ='GDP and Population'!B22 -> 2529.5184 | G35: ='GDP and Population'!D22 -> 244.89592 | H35: ='Gompertz fit'!$B$12*EXP('Gompertz fit'!$B$24*EXP('Gompertz fit'!$B$25*F35)) -> 61.098539 | I35: =$B$13+(0.083333)*($B$14-$B$13) -> 0.038929087 | J35: 27.871
A36: 2028 | C36: =C35*(1+$B$12) -> 19.408639 | D36: =$D$32*(H36*G36)/($H$32*$G$32) -> 19.640025 | E36: =E35*(1+I36) -> 17.394578 | F36: ='GDP and Population'!B23 -> 2592.7564 | G36: ='GDP and Population'!D23 -> 249.85261 | H36: ='Gompertz fit'!$B$12*EXP('Gompertz fit'!$B$24*EXP('Gompertz fit'!$B$25*F36)) -> 64.094963 | I36: =$B$13+(0.111111)*($B$14-$B$13) -> 0.0387238 | J36: 29.7512
A37: 2029 | C37: =C36*(1+$B$12) -> 20.726176 | D37: =$D$32*(H37*G37)/($H$32*$G$32) -> 21.008205 | E37: =E36*(1+I37) -> 18.064591 | F37: ='GDP and Population'!B24 -> 2657.5753 | G37: ='GDP and Population'!D24 -> 254.83964 | H37: ='Gompertz fit'!$B$12*EXP('Gompertz fit'!$B$24*EXP('Gompertz fit'!$B$25*F37)) -> 67.218329 | I37: =$B$13+(0.138889)*($B$14-$B$13) -> 0.038518512 | J37: 31.7583
A38: 2030 | C38: =C37*(1+$B$12) -> 22.133153 | D38: =$D$32*(H38*G38)/($H$32*$G$32) -> 22.458992 | E38: =E37*(1+I38) -> 18.756704 | F38: ='GDP and Population'!B25 -> 2724.0146 | G38: ='GDP and Population'!D25 -> 259.86563 | H38: ='Gompertz fit'!$B$12*EXP('Gompertz fit'!$B$24*EXP('Gompertz fit'!$B$25*F38)) -> 70.470471 | I38: =$B$13+(0.166667)*($B$14-$B$13) -> 0.038313224 | J38: 33.90072
A39: 2031 | C39: =C38*(1+$B$12) -> 23.635641 | D39: =$D$32*(H39*G39)/($H$32*$G$32) -> 23.9926 | E39: =E38*(1+I39) -> 19.471484 | F39: ='GDP and Population'!B26 -> 2792.115 | G39: ='GDP and Population'!D26 -> 264.89631 | H39: ='Gompertz fit'!$B$12*EXP('Gompertz fit'!$B$24*EXP('Gompertz fit'!$B$25*F39)) -> 73.852834 | I39: =$B$13+(0.194444)*($B$14-$B$13) -> 0.038107944 | J39: 35.8432
A40: 2032 | C40: =C39*(1+$B$12) -> 25.240123 | D40: =$D$32*(H40*G40)/($H$32*$G$32) -> 25.613174 | E40: =E39*(1+I40) -> 20.209505 | F40: ='GDP and Population'!B27 -> 2861.9179 | G40: ='GDP and Population'!D27 -> 269.94584 | H40: ='Gompertz fit'!$B$12*EXP('Gompertz fit'!$B$24*EXP('Gompertz fit'!$B$25*F40)) -> 77.366422 | I40: =$B$13+(0.222222)*($B$14-$B$13) -> 0.037902657 | J40: 37.8969
A41: 2033 | C41: =C40*(1+$B$12) -> 26.953525 | D41: =$D$32*(H41*G41)/($H$32*$G$32) -> 27.324289 | E41: =E40*(1+I41) -> 20.97135 | F41: ='GDP and Population'!B28 -> 2933.4658 | G41: ='GDP and Population'!D28 -> 275.02144 | H41: ='Gompertz fit'!$B$12*EXP('Gompertz fit'!$B$24*EXP('Gompertz fit'!$B$25*F41)) -> 81.01176 | I41: =$B$13+(0.25)*($B$14-$B$13) -> 0.037697369 | J41: 40.0683
A42: 2034 | C42: =C41*(1+$B$12) -> 28.783239 | D42: =$D$32*(H42*G42)/($H$32*$G$32) -> 29.125185 | E42: =E41*(1+I42) -> 21.757609 | F42: ='GDP and Population'!B29 -> 3006.8025 | G42: ='GDP and Population'!D29 -> 280.08879 | H42: ='Gompertz fit'!$B$12*EXP('Gompertz fit'!$B$24*EXP('Gompertz fit'!$B$25*F42)) -> 84.788844 | I42: =$B$13+(0.277778)*($B$14-$B$13) -> 0.037492081 | J42: 42.3641
...

Sheet Validation
A1: Validation of the World Bank (2013) vehicle-stock projection against the anchor data
A2: Observed NBS vehicle-population counts show that the 2013 projection overshoots: the WB path implies ~15.4 M vehicles in 2018 against 11.83 M observed (+30%). This model therefore anchors on observed data and retains the WB growth rate only as the upper-bound Scenario A.
A4: Year | B4: Anchor / estimate (M) | C4: Source | D4: WB 2013 projection (M) | E4: WB / anchor | F4: Model, Scenario B (M)
A5: 2010 | B5: 8.671474 | C5: WB Table 22.4 base year | D5: ='Fleet projections'!J18 -> 8.671474 | E5: =IF(D5="","",D5/B5) -> 1 | F5: ='Fleet projections'!D18 -> 8.671474
A6: 2017 | B6: 11.45837 | C6: NBS Q1 2017 | D6: ='Fleet projections'!J25 -> 14.2596 | E6: =IF(D6="","",D6/B6) -> 1.2444702 | F6: ='Fleet projections'!D25 -> 11.45837
A7: 2017.75 | B7: 11.547236 | C7: NBS Q3 2017 | D7: ='Fleet projections'!J26 -> 15.3098 | E7: =IF(D7="","",D7/B7) -> 1.3258411 | F7: ='Fleet projections'!D26 -> 11.826033
A8: 2018.25 | B8: 11.653871 | C8: NBS Q1 2018 | D8: ='Fleet projections'!J26 -> 15.3098 | E8: =IF(D8="","",D8/B8) -> 1.3137094 | F8: ='Fleet projections'!D26 -> 11.826033
A9: 2018 | B9: 11.826033 | C9: NBS Q4 2018 | D9: ='Fleet projections'!J26 -> 15.3098 | E9: =IF(D9="","",D9/B9) -> 1.2945846 | F9: ='Fleet projections'!D26 -> 11.826033
A10: 2020 | B10: 11.605207 | C10: CEIC/OICA (modelled; different methodology) | D10: ='Fleet projections'!J28 -> 17.647653 | E10: =IF(D10="","",D10/B10) -> 1.5206668 | F10: ='Fleet projections'!D28 -> 12.779846
A11: 2023 | B11: 12 | C11: FRSC / NIA round estimate (low confidence) | D11: ='Fleet projections'!J31 -> 21.4656 | E11: =IF(D11="","",D11/B11) -> 1.7888 | F11: ='Fleet projections'!D31 -> 14.356727
A13: Implied CAGR 2010-2018, anchor-derived: | B13: ='Fleet projections'!B11 -> 0.039544943
A14: Implied CAGR 2010-2035, WB 2013 projection: | B14: ='Fleet projections'!B12 -> 0.067884039
A16: Scenario endpoints 2060 (M):
A17: Scenario A (upper, WB growth rate) | B17: ='Fleet projections'!C68 -> 158.76916 | C17: =B17*1000/'GDP and Population'!D55 -> 399.00586 | D17: vehicles per 1,000 persons in 2060 (col C); South Africa ~176, Morocco ~112, Libya ~490 today (OICA).
A18: Scenario B (central, Gompertz gamma=300) | B18: ='Fleet projections'!D68 -> 104.02324 | C18: =B18*1000/'GDP and Population'!D55 -> 261.42283 | D18: vehicles per 1,000 persons in 2060 (col C); South Africa ~176, Morocco ~112, Libya ~490 today (OICA).
A19: Scenario C (lower, declining CAGR) | B19: ='Fleet projections'!E68 -> 52.844585 | C19: =B19*1000/'GDP and Population'!D55 -> 132.80475 | D19: vehicles per 1,000 persons in 2060 (col C); South Africa ~176, Morocco ~112, Libya ~490 today (OICA).

Sheet EV adoption
A1: EV adoption share by class and year (logistic S-curves)
A3: Year | B3: Motorcycle | C3: Private car | D3: Light commercial | E3: Heavy goods | F3: Light bus | G3: Coach
A4: 2010 | B4: =IF(A4<2025,0,(1/(1+EXP(-Assumptions!$C$16*(A4-Assumptions!$B$16))))/IF(Assumptions!$B$92=1,1/(1+EXP(-Assumptions!$C$16*(2060-Assumptions!$B$16))),1)) -> 0 | C4: =IF(A4<2025,0,(1/(1+EXP(-Assumptions!$C$17*(A4-Assumptions!$B$17))))/IF(Assumptions!$B$92=1,1/(1+EXP(-Assumptions!$C$17*(2060-Assumptions!$B$17))),1)) -> 0 | D4: =IF(A4<2025,0,(1/(1+EXP(-Assumptions!$C$18*(A4-Assumptions!$B$18))))/IF(Assumptions!$B$92=1,1/(1+EXP(-Assumptions!$C$18*(2060-Assumptions!$B$18))),1)) -> 0 | E4: =IF(A4<2025,0,(1/(1+EXP(-Assumptions!$C$19*(A4-Assumptions!$B$19))))/IF(Assumptions!$B$92=1,1/(1+EXP(-Assumptions!$C$19*(2060-Assumptions!$B$19))),1)) -> 0 | F4: =IF(A4<2025,0,(1/(1+EXP(-Assumptions!$C$20*(A4-Assumptions!$B$20))))/IF(Assumptions!$B$92=1,1/(1+EXP(-Assumptions!$C$20*(2060-Assumptions!$B$20))),1)) -> 0 | G4: =IF(A4<2025,0,(1/(1+EXP(-Assumptions!$C$21*(A4-Assumptions!$B$21))))/IF(Assumptions!$B$92=1,1/(1+EXP(-Assumptions!$C$21*(2060-Assumptions!$B$21))),1)) -> 0
A5: 2011 | B5: =IF(A5<2025,0,(1/(1+EXP(-Assumptions!$C$16*(A5-Assumptions!$B$16))))/IF(Assumptions!$B$92=1,1/(1+EXP(-Assumptions!$C$16*(2060-Assumptions!$B$16))),1)) -> 0 | C5: =IF(A5<2025,0,(1/(1+EXP(-Assumptions!$C$17*(A5-Assumptions!$B$17))))/IF(Assumptions!$B$92=1,1/(1+EXP(-Assumptions!$C$17*(2060-Assumptions!$B$17))),1)) -> 0 | D5: =IF(A5<2025,0,(1/(1+EXP(-Assumptions!$C$18*(A5-Assumptions!$B$18))))/IF(Assumptions!$B$92=1,1/(1+EXP(-Assumptions!$C$18*(2060-Assumptions!$B$18))),1)) -> 0 | E5: =IF(A5<2025,0,(1/(1+EXP(-Assumptions!$C$19*(A5-Assumptions!$B$19))))/IF(Assumptions!$B$92=1,1/(1+EXP(-Assumptions!$C$19*(2060-Assumptions!$B$19))),1)) -> 0 | F5: =IF(A5<2025,0,(1/(1+EXP(-Assumptions!$C$20*(A5-Assumptions!$B$20))))/IF(Assumptions!$B$92=1,1/(1+EXP(-Assumptions!$C$20*(2060-Assumptions!$B$20))),1)) -> 0 | G5: =IF(A5<2025,0,(1/(1+EXP(-Assumptions!$C$21*(A5-Assumptions!$B$21))))/IF(Assumptions!$B$92=1,1/(1+EXP(-Assumptions!$C$21*(2060-Assumptions!$B$21))),1)) -> 0
A6: 2012 | B6: =IF(A6<2025,0,(1/(1+EXP(-Assumptions!$C$16*(A6-Assumptions!$B$16))))/IF(Assumptions!$B$92=1,1/(1+EXP(-Assumptions!$C$16*(2060-Assumptions!$B$16))),1)) -> 0 | C6: =IF(A6<2025,0,(1/(1+EXP(-Assumptions!$C$17*(A6-Assumptions!$B$17))))/IF(Assumptions!$B$92=1,1/(1+EXP(-Assumptions!$C$17*(2060-Assumptions!$B$17))),1)) -> 0 | D6: =IF(A6<2025,0,(1/(1+EXP(-Assumptions!$C$18*(A6-Assumptions!$B$18))))/IF(Assumptions!$B$92=1,1/(1+EXP(-Assumptions!$C$18*(2060-Assumptions!$B$18))),1)) -> 0 | E6: =IF(A6<2025,0,(1/(1+EXP(-Assumptions!$C$19*(A6-Assumptions!$B$19))))/IF(Assumptions!$B$92=1,1/(1+EXP(-Assumptions!$C$19*(2060-Assumptions!$B$19))),1)) -> 0 | F6: =IF(A6<2025,0,(1/(1+EXP(-Assumptions!$C$20*(A6-Assumptions!$B$20))))/IF(Assumptions!$B$92=1,1/(1+EXP(-Assumptions!$C$20*(2060-Assumptions!$B$20))),1)) -> 0 | G6: =IF(A6<2025,0,(1/(1+EXP(-Assumptions!$C$21*(A6-Assumptions!$B$21))))/IF(Assumptions!$B$92=1,1/(1+EXP(-Assumptions!$C$21*(2060-Assumptions!$B$21))),1)) -> 0
A7: 2013 | B7: =IF(A7<2025,0,(1/(1+EXP(-Assumptions!$C$16*(A7-Assumptions!$B$16))))/IF(Assumptions!$B$92=1,1/(1+EXP(-Assumptions!$C$16*(2060-Assumptions!$B$16))),1)) -> 0 | C7: =IF(A7<2025,0,(1/(1+EXP(-Assumptions!$C$17*(A7-Assumptions!$B$17))))/IF(Assumptions!$B$92=1,1/(1+EXP(-Assumptions!$C$17*(2060-Assumptions!$B$17))),1)) -> 0 | D7: =IF(A7<2025,0,(1/(1+EXP(-Assumptions!$C$18*(A7-Assumptions!$B$18))))/IF(Assumptions!$B$92=1,1/(1+EXP(-Assumptions!$C$18*(2060-Assumptions!$B$18))),1)) -> 0 | E7: =IF(A7<2025,0,(1/(1+EXP(-Assumptions!$C$19*(A7-Assumptions!$B$19))))/IF(Assumptions!$B$92=1,1/(1+EXP(-Assumptions!$C$19*(2060-Assumptions!$B$19))),1)) -> 0 | F7: =IF(A7<2025,0,(1/(1+EXP(-Assumptions!$C$20*(A7-Assumptions!$B$20))))/IF(Assumptions!$B$92=1,1/(1+EXP(-Assumptions!$C$20*(2060-Assumptions!$B$20))),1)) -> 0 | G7: =IF(A7<2025,0,(1/(1+EXP(-Assumptions!$C$21*(A7-Assumptions!$B$21))))/IF(Assumptions!$B$92=1,1/(1+EXP(-Assumptions!$C$21*(2060-Assumptions!$B$21))),1)) -> 0
A8: 2014 | B8: =IF(A8<2025,0,(1/(1+EXP(-Assumptions!$C$16*(A8-Assumptions!$B$16))))/IF(Assumptions!$B$92=1,1/(1+EXP(-Assumptions!$C$16*(2060-Assumptions!$B$16))),1)) -> 0 | C8: =IF(A8<2025,0,(1/(1+EXP(-Assumptions!$C$17*(A8-Assumptions!$B$17))))/IF(Assumptions!$B$92=1,1/(1+EXP(-Assumptions!$C$17*(2060-Assumptions!$B$17))),1)) -> 0 | D8: =IF(A8<2025,0,(1/(1+EXP(-Assumptions!$C$18*(A8-Assumptions!$B$18))))/IF(Assumptions!$B$92=1,1/(1+EXP(-Assumptions!$C$18*(2060-Assumptions!$B$18))),1)) -> 0 | E8: =IF(A8<2025,0,(1/(1+EXP(-Assumptions!$C$19*(A8-Assumptions!$B$19))))/IF(Assumptions!$B$92=1,1/(1+EXP(-Assumptions!$C$19*(2060-Assumptions!$B$19))),1)) -> 0 | F8: =IF(A8<2025,0,(1/(1+EXP(-Assumptions!$C$20*(A8-Assumptions!$B$20))))/IF(Assumptions!$B$92=1,1/(1+EXP(-Assumptions!$C$20*(2060-Assumptions!$B$20))),1)) -> 0 | G8: =IF(A8<2025,0,(1/(1+EXP(-Assumptions!$C$21*(A8-Assumptions!$B$21))))/IF(Assumptions!$B$92=1,1/(1+EXP(-Assumptions!$C$21*(2060-Assumptions!$B$21))),1)) -> 0
A9: 2015 | B9: =IF(A9<2025,0,(1/(1+EXP(-Assumptions!$C$16*(A9-Assumptions!$B$16))))/IF(Assumptions!$B$92=1,1/(1+EXP(-Assumptions!$C$16*(2060-Assumptions!$B$16))),1)) -> 0 | C9: =IF(A9<2025,0,(1/(1+EXP(-Assumptions!$C$17*(A9-Assumptions!$B$17))))/IF(Assumptions!$B$92=1,1/(1+EXP(-Assumptions!$C$17*(2060-Assumptions!$B$17))),1)) -> 0 | D9: =IF(A9<2025,0,(1/(1+EXP(-Assumptions!$C$18*(A9-Assumptions!$B$18))))/IF(Assumptions!$B$92=1,1/(1+EXP(-Assumptions!$C$18*(2060-Assumptions!$B$18))),1)) -> 0 | E9: =IF(A9<2025,0,(1/(1+EXP(-Assumptions!$C$19*(A9-Assumptions!$B$19))))/IF(Assumptions!$B$92=1,1/(1+EXP(-Assumptions!$C$19*(2060-Assumptions!$B$19))),1)) -> 0 | F9: =IF(A9<2025,0,(1/(1+EXP(-Assumptions!$C$20*(A9-Assumptions!$B$20))))/IF(Assumptions!$B$92=1,1/(1+EXP(-Assumptions!$C$20*(2060-Assumptions!$B$20))),1)) -> 0 | G9: =IF(A9<2025,0,(1/(1+EXP(-Assumptions!$C$21*(A9-Assumptions!$B$21))))/IF(Assumptions!$B$92=1,1/(1+EXP(-Assumptions!$C$21*(2060-Assumptions!$B$21))),1)) -> 0
A10: 2016 | B10: =IF(A10<2025,0,(1/(1+EXP(-Assumptions!$C$16*(A10-Assumptions!$B$16))))/IF(Assumptions!$B$92=1,1/(1+EXP(-Assumptions!$C$16*(2060-Assumptions!$B$16))),1)) -> 0 | C10: =IF(A10<2025,0,(1/(1+EXP(-Assumptions!$C$17*(A10-Assumptions!$B$17))))/IF(Assumptions!$B$92=1,1/(1+EXP(-Assumptions!$C$17*(2060-Assumptions!$B$17))),1)) -> 0 | D10: =IF(A10<2025,0,(1/(1+EXP(-Assumptions!$C$18*(A10-Assumptions!$B$18))))/IF(Assumptions!$B$92=1,1/(1+EXP(-Assumptions!$C$18*(2060-Assumptions!$B$18))),1)) -> 0 | E10: =IF(A10<2025,0,(1/(1+EXP(-Assumptions!$C$19*(A10-Assumptions!$B$19))))/IF(Assumptions!$B$92=1,1/(1+EXP(-Assumptions!$C$19*(2060-Assumptions!$B$19))),1)) -> 0 | F10: =IF(A10<2025,0,(1/(1+EXP(-Assumptions!$C$20*(A10-Assumptions!$B$20))))/IF(Assumptions!$B$92=1,1/(1+EXP(-Assumptions!$C$20*(2060-Assumptions!$B$20))),1)) -> 0 | G10: =IF(A10<2025,0,(1/(1+EXP(-Assumptions!$C$21*(A10-Assumptions!$B$21))))/IF(Assumptions!$B$92=1,1/(1+EXP(-Assumptions!$C$21*(2060-Assumptions!$B$21))),1)) -> 0
A11: 2017 | B11: =IF(A11<2025,0,(1/(1+EXP(-Assumptions!$C$16*(A11-Assumptions!$B$16))))/IF(Assumptions!$B$92=1,1/(1+EXP(-Assumptions!$C$16*(2060-Assumptions!$B$16))),1)) -> 0 | C11: =IF(A11<2025,0,(1/(1+EXP(-Assumptions!$C$17*(A11-Assumptions!$B$17))))/IF(Assumptions!$B$92=1,1/(1+EXP(-Assumptions!$C$17*(2060-Assumptions!$B$17))),1)) -> 0 | D11: =IF(A11<2025,0,(1/(1+EXP(-Assumptions!$C$18*(A11-Assumptions!$B$18))))/IF(Assumptions!$B$92=1,1/(1+EXP(-Assumptions!$C$18*(2060-Assumptions!$B$18))),1)) -> 0 | E11: =IF(A11<2025,0,(1/(1+EXP(-Assumptions!$C$19*(A11-Assumptions!$B$19))))/IF(Assumptions!$B$92=1,1/(1+EXP(-Assumptions!$C$19*(2060-Assumptions!$B$19))),1)) -> 0 | F11: =IF(A11<2025,0,(1/(1+EXP(-Assumptions!$C$20*(A11-Assumptions!$B$20))))/IF(Assumptions!$B$92=1,1/(1+EXP(-Assumptions!$C$20*(2060-Assumptions!$B$20))),1)) -> 0 | G11: =IF(A11<2025,0,(1/(1+EXP(-Assumptions!$C$21*(A11-Assumptions!$B$21))))/IF(Assumptions!$B$92=1,1/(1+EXP(-Assumptions!$C$21*(2060-Assumptions!$B$21))),1)) -> 0
A12: 2018 | B12: =IF(A12<2025,0,(1/(1+EXP(-Assumptions!$C$16*(A12-Assumptions!$B$16))))/IF(Assumptions!$B$92=1,1/(1+EXP(-Assumptions!$C$16*(2060-Assumptions!$B$16))),1)) -> 0 | C12: =IF(A12<2025,0,(1/(1+EXP(-Assumptions!$C$17*(A12-Assumptions!$B$17))))/IF(Assumptions!$B$92=1,1/(1+EXP(-Assumptions!$C$17*(2060-Assumptions!$B$17))),1)) -> 0 | D12: =IF(A12<2025,0,(1/(1+EXP(-Assumptions!$C$18*(A12-Assumptions!$B$18))))/IF(Assumptions!$B$92=1,1/(1+EXP(-Assumptions!$C$18*(2060-Assumptions!$B$18))),1)) -> 0 | E12: =IF(A12<2025,0,(1/(1+EXP(-Assumptions!$C$19*(A12-Assumptions!$B$19))))/IF(Assumptions!$B$92=1,1/(1+EXP(-Assumptions!$C$19*(2060-Assumptions!$B$19))),1)) -> 0 | F12: =IF(A12<2025,0,(1/(1+EXP(-Assumptions!$C$20*(A12-Assumptions!$B$20))))/IF(Assumptions!$B$92=1,1/(1+EXP(-Assumptions!$C$20*(2060-Assumptions!$B$20))),1)) -> 0 | G12: =IF(A12<2025,0,(1/(1+EXP(-Assumptions!$C$21*(A12-Assumptions!$B$21))))/IF(Assumptions!$B$92=1,1/(1+EXP(-Assumptions!$C$21*(2060-Assumptions!$B$21))),1)) -> 0
A13: 2019 | B13: =IF(A13<2025,0,(1/(1+EXP(-Assumptions!$C$16*(A13-Assumptions!$B$16))))/IF(Assumptions!$B$92=1,1/(1+EXP(-Assumptions!$C$16*(2060-Assumptions!$B$16))),1)) -> 0 | C13: =IF(A13<2025,0,(1/(1+EXP(-Assumptions!$C$17*(A13-Assumptions!$B$17))))/IF(Assumptions!$B$92=1,1/(1+EXP(-Assumptions!$C$17*(2060-Assumptions!$B$17))),1)) -> 0 | D13: =IF(A13<2025,0,(1/(1+EXP(-Assumptions!$C$18*(A13-Assumptions!$B$18))))/IF(Assumptions!$B$92=1,1/(1+EXP(-Assumptions!$C$18*(2060-Assumptions!$B$18))),1)) -> 0 | E13: =IF(A13<2025,0,(1/(1+EXP(-Assumptions!$C$19*(A13-Assumptions!$B$19))))/IF(Assumptions!$B$92=1,1/(1+EXP(-Assumptions!$C$19*(2060-Assumptions!$B$19))),1)) -> 0 | F13: =IF(A13<2025,0,(1/(1+EXP(-Assumptions!$C$20*(A13-Assumptions!$B$20))))/IF(Assumptions!$B$92=1,1/(1+EXP(-Assumptions!$C$20*(2060-Assumptions!$B$20))),1)) -> 0 | G13: =IF(A13<2025,0,(1/(1+EXP(-Assumptions!$C$21*(A13-Assumptions!$B$21))))/IF(Assumptions!$B$92=1,1/(1+EXP(-Assumptions!$C$21*(2060-Assumptions!$B$21))),1)) -> 0
A14: 2020 | B14: =IF(A14<2025,0,(1/(1+EXP(-Assumptions!$C$16*(A14-Assumptions!$B$16))))/IF(Assumptions!$B$92=1,1/(1+EXP(-Assumptions!$C$16*(2060-Assumptions!$B$16))),1)) -> 0 | C14: =IF(A14<2025,0,(1/(1+EXP(-Assumptions!$C$17*(A14-Assumptions!$B$17))))/IF(Assumptions!$B$92=1,1/(1+EXP(-Assumptions!$C$17*(2060-Assumptions!$B$17))),1)) -> 0 | D14: =IF(A14<2025,0,(1/(1+EXP(-Assumptions!$C$18*(A14-Assumptions!$B$18))))/IF(Assumptions!$B$92=1,1/(1+EXP(-Assumptions!$C$18*(2060-Assumptions!$B$18))),1)) -> 0 | E14: =IF(A14<2025,0,(1/(1+EXP(-Assumptions!$C$19*(A14-Assumptions!$B$19))))/IF(Assumptions!$B$92=1,1/(1+EXP(-Assumptions!$C$19*(2060-Assumptions!$B$19))),1)) -> 0 | F14: =IF(A14<2025,0,(1/(1+EXP(-Assumptions!$C$20*(A14-Assumptions!$B$20))))/IF(Assumptions!$B$92=1,1/(1+EXP(-Assumptions!$C$20*(2060-Assumptions!$B$20))),1)) -> 0 | G14: =IF(A14<2025,0,(1/(1+EXP(-Assumptions!$C$21*(A14-Assumptions!$B$21))))/IF(Assumptions!$B$92=1,1/(1+EXP(-Assumptions!$C$21*(2060-Assumptions!$B$21))),1)) -> 0
A15: 2021 | B15: =IF(A15<2025,0,(1/(1+EXP(-Assumptions!$C$16*(A15-Assumptions!$B$16))))/IF(Assumptions!$B$92=1,1/(1+EXP(-Assumptions!$C$16*(2060-Assumptions!$B$16))),1)) -> 0 | C15: =IF(A15<2025,0,(1/(1+EXP(-Assumptions!$C$17*(A15-Assumptions!$B$17))))/IF(Assumptions!$B$92=1,1/(1+EXP(-Assumptions!$C$17*(2060-Assumptions!$B$17))),1)) -> 0 | D15: =IF(A15<2025,0,(1/(1+EXP(-Assumptions!$C$18*(A15-Assumptions!$B$18))))/IF(Assumptions!$B$92=1,1/(1+EXP(-Assumptions!$C$18*(2060-Assumptions!$B$18))),1)) -> 0 | E15: =IF(A15<2025,0,(1/(1+EXP(-Assumptions!$C$19*(A15-Assumptions!$B$19))))/IF(Assumptions!$B$92=1,1/(1+EXP(-Assumptions!$C$19*(2060-Assumptions!$B$19))),1)) -> 0 | F15: =IF(A15<2025,0,(1/(1+EXP(-Assumptions!$C$20*(A15-Assumptions!$B$20))))/IF(Assumptions!$B$92=1,1/(1+EXP(-Assumptions!$C$20*(2060-Assumptions!$B$20))),1)) -> 0 | G15: =IF(A15<2025,0,(1/(1+EXP(-Assumptions!$C$21*(A15-Assumptions!$B$21))))/IF(Assumptions!$B$92=1,1/(1+EXP(-Assumptions!$C$21*(2060-Assumptions!$B$21))),1)) -> 0
... A54: 2060 | B54: =IF(A54<2025,0,(1/(1+EXP(-Assumptions!$C$16*(A54-Assumptions!$B$16))))/IF(Assumptions!$B$92=1,1/(1+EXP(-Assumptions!$C$16*(2060-Assumptions!$B$16))),1)) -> 0.9797293 | C54: =IF(A54<2025,0,(1/(1+EXP(-Assumptions!$C$17*(A54-Assumptions!$B$17))))/IF(Assumptions!$B$92=1,1/(1+EXP(-Assumptions!$C$17*(2060-Assumptions!$B$17))),1)) -> 0.95009307 | D54: =IF(A54<2025,0,(1/(1+EXP(-Assumptions!$C$18*(A54-Assumptions!$B$18))))/IF(Assumptions!$B$92=1,1/(1+EXP(-Assumptions!$C$18*(2060-Assumptions!$B$18))),1)) -> 0.919945 | E54: =IF(A54<2025,0,(1/(1+EXP(-Assumptions!$C$19*(A54-Assumptions!$B$19))))/IF(Assumptions!$B$92=1,1/(1+EXP(-Assumptions!$C$19*(2060-Assumptions!$B$19))),1)) -> 0.80009688 | F54: =IF(A54<2025,0,(1/(1+EXP(-Assumptions!$C$20*(A54-Assumptions!$B$20))))/IF(Assumptions!$B$92=1,1/(1+EXP(-Assumptions!$C$20*(2060-Assumptions!$B$20))),1)) -> 0.95069182 | G54: =IF(A54<2025,0,(1/(1+EXP(-Assumptions!$C$21*(A54-Assumptions!$B$21))))/IF(Assumptions!$B$92=1,1/(1+EXP(-Assumptions!$C$21*(2060-Assumptions!$B$21))),1)) -> 0.90024951

Sheet Load profile
A1: Hourly charging profile under managed (smart) charging and derived load factor
A2: Each column gives the share of that charger segment's daily energy delivered in each hour (sums to 100%). Segment weights (row 30) are the segment's share of 2060 central-case at-wall energy. The aggregate hourly profile is the weighted sum; LF = mean / max. Managed charging shifts home and depot charging into the 22:00-06:00 window and workplace charging into 09:00-15:00 (solar hours). Profiles are stylised, informed by Lukuyu et al. (2024, Sci. Rep.) for African cities and NREL/ICCT load-profile conventions.
A4: Hour | B4: Home (L1+L2, managed overnight) | C4: Workplace/public AC (daytime) | D4: Public DC fast | E4: Depot HD (managed overnight) | F4: Battery swap (distributed) | G4: Aggregate share
A5: 0 | B5: 0.1 | C5: 0 | D5: 0.0097 | E5: 0.11 | F5: 0.0196 | G5: =SUMPRODUCT(B5:F5,$B$30:$F$30) -> 0.068516558
A6: 1 | B6: 0.1 | C6: 0 | D6: 0.0097 | E6: 0.11 | F6: 0.0196 | G6: =SUMPRODUCT(B6:F6,$B$30:$F$30) -> 0.068516558
A7: 2 | B7: 0.1 | C7: 0 | D7: 0.0097 | E7: 0.11 | F7: 0.0196 | G7: =SUMPRODUCT(B7:F7,$B$30:$F$30) -> 0.068516558
A8: 3 | B8: 0.1 | C8: 0 | D8: 0.0097 | E8: 0.11 | F8: 0.0196 | G8: =SUMPRODUCT(B8:F8,$B$30:$F$30) -> 0.068516558
A9: 4 | B9: 0.1 | C9: 0 | D9: 0.0097 | E9: 0.11 | F9: 0.0196 | G9: =SUMPRODUCT(B9:F9,$B$30:$F$30) -> 0.068516558
A10: 5 | B10: 0.09 | C10: 0 | D10: 0.0194 | E10: 0.1 | F10: 0.0294 | G10: =SUMPRODUCT(B10:F10,$B$30:$F$30) -> 0.063879872
A11: 6 | B11: 0.05 | C11: 0 | D11: 0.0388 | E11: 0.04 | F11: 0.049 | G11: =SUMPRODUCT(B11:F11,$B$30:$F$30) -> 0.034105705
A12: 7 | B12: 0.01 | C12: 0.02 | D12: 0.0583 | E12: 0 | F12: 0.0588 | G12: =SUMPRODUCT(B12:F12,$B$30:$F$30) -> 0.016167991
A13: 8 | B13: 0 | C13: 0.06 | D13: 0.068 | E13: 0 | F13: 0.0588 | G13: =SUMPRODUCT(B13:F13,$B$30:$F$30) -> 0.02349818
A14: 9 | B14: 0 | C14: 0.12 | D14: 0.068 | E14: 0 | F14: 0.0588 | G14: =SUMPRODUCT(B14:F14,$B$30:$F$30) -> 0.03589763
A15: 10 | B15: 0 | C15: 0.14 | D15: 0.068 | E15: 0 | F15: 0.0588 | G15: =SUMPRODUCT(B15:F15,$B$30:$F$30) -> 0.040030781
A16: 11 | B16: 0 | C16: 0.14 | D16: 0.068 | E16: 0 | F16: 0.0588 | G16: =SUMPRODUCT(B16:F16,$B$30:$F$30) -> 0.040030781
... A28: 23 | B28: 0.1 | C28: 0 | D28: 0.0097 | E28: 0.08 | F28: 0.0196 | G28: =SUMPRODUCT(B28:F28,$B$30:$F$30) -> 0.056549706
A29: Column sums | B29: =SUM(B5:B28) -> 1 | C29: =SUM(C5:C28) -> 1 | D29: =SUM(D5:D28) -> 1.0003 | E29: =SUM(E5:E28) -> 1 | F29: =SUM(F5:F28) -> 0.9996
A30: Segment energy weight (2060, Scenario B) | B30: =(B37*Assumptions!$D$7+B38*Assumptions!$D$8+B36*Assumptions!$D$6*Assumptions!$B$88/Assumptions!$B$6)/$B$42 -> 0.22724962 | C30: =((B37*(1-Assumptions!$D$7)+B38*(1-Assumptions!$D$8))*0.6)/$B$42 -> 0.20665751 | D30: =((B37*(1-Assumptions!$D$7)+B38*(1-Assumptions!$D$8))*0.4)/$B$42 -> 0.13777167 | E30: =(B39+B40+B41)/$B$42 -> 0.39889507 | F30: =B36*(1-Assumptions!$D$6)*Assumptions!$B$89/Assumptions!$B$6/$B$42 -> 0.029426126 | G30: Non-home LDV energy split 60% public AC / 40% DC fast (stylised).
A32: Load factor LF = mean hourly share / max hourly share: | B32: =AVERAGE(G5:G28)/MAX(G5:G28) -> 0.60814349
A33: Peak hour (0-23): | B33: =INDEX(A5:A28,MATCH(MAX(G5:G28),G5:G28,0)) -> 0
A35: Energy-by-segment weights (2060, Scenario B at-wall TWh)
A36: Motorcycle TWh | B36: ='Results Scenario B'!C39*Assumptions!$B$6*Assumptions!$C$6*Assumptions!$B$61/1000000000 -> 21.559013
A37: Private car TWh | B37: ='Results Scenario B'!D39*Assumptions!$B$7*Assumptions!$C$7*Assumptions!$B$61/1000000000 -> 276.98048
A38: LCV TWh | B38: ='Results Scenario B'!E39*Assumptions!$B$8*Assumptions!$C$8*Assumptions!$B$61/1000000000 -> 38.367161
A39: HGV TWh | B39: ='Results Scenario B'!F39*Assumptions!$B$9*Assumptions!$C$9*Assumptions!$B$61/1000000000 -> 218.36119
A40: Light bus TWh | B40: ='Results Scenario B'!G39*Assumptions!$B$10*Assumptions!$C$10*Assumptions!$B$61/1000000000 -> 1.2562796
A41: Coach TWh | B41: ='Results Scenario B'!H39*Assumptions!$B$11*Assumptions!$C$11*Assumptions!$B$61/1000000000 -> 3.9548224
A42: Total TWh | B42: =SUM(B36:B41) -> 560.47895
A44: Load factor by year (same hourly profiles, each year's charging mix; Scenario B energy by class) | I44: Year | J44: 2025 | K44: 2026 | L44: 2027 | M44: 2028 | N44: 2029 | O44: 2030 | P44: 2031 | Q44: 2032 | R44: 2033 | S44: 2034 | T44: 2035 | U44: 2036 | V44: 2037 | W44: 2038 | X44: 2039 | Y44: 2040 | Z44: 2041 | AA44: 2042 | AB44: 2043 | AC44: 2044 | AD44: 2045 | AE44: 2046 | AF44: 2047 | AG44: 2048 | AH44: 2049 | AI44: 2050 | AJ44: 2051 | AK44: 2052 | AL44: 2053 | AM44: 2054 | AN44: 2055 | AO44: 2056 | AP44: 2057 | AQ44: 2058 | AR44: 2059 | AS44: 2060
