Workbook

Sheet Macro-Economic_Demographic Data
A1: World Population Prospects 2024
A3: Year | B3: Total Population, as of 1 January (thousands) | C3: National Total Population, as of 1 January | D3: Urbanization (% of pupulation in Urban Areas) | E3: Rural Population | F3: Urban Population | G3: National Average Household Size | H3: Rural Average Household Size | I3: Urban Average Household Size | J3: Household size CAGR from 1960 - 2024 | K3: National Total Number of Households | L3: Rural Total Number of Households | M3: Urban Total Number of Households | N3: GDP (constant 2015 US$) | O3: GDP (constant 2015 US$) Annual Growth Rate | P3: GDP/Capita (constant 2015 US$) | Q3: GDP at 2010 Constant Basic Prices (₦' Billion) | S3: GDP/Capita (2010 Basic Price ₦) | U3: GDP, PPP (constant 2021 international $) | V3: GDP (constant 2021 international $) Annual Growth Rate | W3: GDP (constant 2021 international $) | X3: Access to electricity (% of population) | Y3: Access to electricity, rural (% of rural population) | Z3: Access to electricity, urban (% of urban population)
A4: 1995 | B4: 109367.38 | C4: =B4*1000 -> 109367384 | D4: 39.13641 | E4: =C4-F4 -> 66564916 | F4: =(D4*C4)/100 -> 42802468 | N4: 1.546014e+11 | P4: =N4/C4 -> 1413.597 | Q4: 21660.487 | S4: =(Q4*10^9)/(C4) -> 198052.53 | U4: 5.3165748e+11 | W4: =U4/C4 -> 4861.2069 | X4: 38.687252 | Y4: 17.159768 | Z4: 84.004929
A5: 1996 | B5: 112271.47 | C5: =B5*1000 -> 112271472 | D5: 39.950356 | E5: =C5-F5 -> 67418619 | F5: =(D5*C5)/100 -> 44852853 | N5: 1.6108836e+11 | O5: =(N5-N4)/N4 -> 0.04195924 | P5: =N5/C5 -> 1434.8111 | Q5: 22568.867 | R5: =(Q5-Q4)/Q4 -> 0.041937176 | S5: =(Q5*10^9)/(C5) -> 201020.49 | U5: 5.5396543e+11 | V5: =(U5-U4)/U4 -> 0.04195924 | W5: =U5/C5 -> 4934.1602 | X5: 39.545319 | Y5: 17.903206 | Z5: 84.036476
A6: 1997 | B6: 115238.09 | C6: =B6*1000 -> 115238085 | D6: 40.772017 | E6: =C6-F6 -> 68253193 | F6: =(D6*C6)/100 -> 46984892 | N6: 1.6581968e+11 | O6: =(N6-N5)/N5 -> 0.029370994 | P6: =N6/C6 -> 1438.9313 | Q6: 23231.123 | R6: =(Q6-Q5)/Q5 -> 0.029343804 | S6: =(Q6*10^9)/(C6) -> 201592.41 | U6: 5.7023594e+11 | V6: =(U6-U5)/U5 -> 0.029370994 | W6: =U6/C6 -> 4948.3289 | X6: 40.399982 | Y6: 18.658547 | Z6: 84.052223
A7: 1998 | B7: 118271.5 | C7: =B7*1000 -> 118271498 | D7: 41.600914 | E7: =C7-F7 -> 69069473 | F7: =(D7*C7)/100 -> 49202025 | N7: 1.7009991e+11 | O7: =(N7-N6)/N6 -> 0.025812541 | P7: =N7/C7 -> 1438.2156 | Q7: 23829.758 | R7: =(Q7-Q6)/Q6 -> 0.025768677 | S7: =(Q7*10^9)/(C7) -> 201483.53 | U7: 5.8495518e+11 | V7: =(U7-U6)/U6 -> 0.025812541 | W7: =U7/C7 -> 4945.8677 | X7: 41.250568 | Y7: 19.425149 | Z7: 84.049019
A8: 1999 | B8: 121421.01 | C8: =B8*1000 -> 121421011 | D8: 42.43657 | E8: =C8-F8 -> 69894099 | F8: =(D8*C8)/100 -> 51526912 | N8: 1.7109351e+11 | O8: =(N8-N7)/N7 -> 0.0058412689 | P8: =N8/C8 -> 1409.0931 | Q8: 23967.591 | R8: =(Q8-Q7)/Q7 -> 0.0057840701 | S8: =(Q8*10^9)/(C8) -> 197392.45 | U8: 5.8837206e+11 | V8: =(U8-U7)/U7 -> 0.0058412689 | W8: =U8/C8 -> 4845.7187 | X8: 44.9 | Y8: 24.32679 | Z8: 84.3
A9: 2000 | B9: 124673.63 | C9: =B9*1000 -> 124673629 | D9: 43.278505 | E9: =C9-F9 -> 70716746 | F9: =(D9*C9)/100 -> 53956883 | N9: 1.7967545e+11 | O9: =(N9-N8)/N8 -> 0.050159348 | P9: =N9/C9 -> 1441.1664 | Q9: 25169.539 | R9: =(Q9-Q8)/Q8 -> 0.050148859 | S9: =(Q9*10^9)/(C9) -> 201883.42 | U9: 6.1788442e+11 | V9: =(U9-U8)/U8 -> 0.050159348 | W9: =U9/C9 -> 4956.0154 | X9: 43.2 | Y9: 21.5 | Z9: 83.8
A10: 2001 | B10: 128091.36 | C10: =B10*1000 -> 128091359 | D10: 44.126242 | E10: =C10-F10 -> 71569456 | F10: =(D10*C10)/100 -> 56521903 | N10: 1.9030808e+11 | O10: =(N10-N9)/N9 -> 0.059176846 | P10: =N10/C10 -> 1485.7214 | Q10: 26658.621 | R10: =(Q10-Q9)/Q9 -> 0.059162089 | S10: =(Q10*10^9)/(C10) -> 208121.93 | U10: 6.5444887e+11 | V10: =(U10-U9)/U9 -> 0.059176846 | W10: =U10/C10 -> 5109.2351 | X10: 43.9 | Y10: 21.8 | Z10: 83.8
A11: 2002 | B11: 131633.83 | C11: =B11*1000 -> 131633830 | D11: 44.979303 | E11: =C11-F11 -> 72425851 | F11: =(D11*C11)/100 -> 59207979 | N11: 2.194807e+11 | O11: =(N11-N10)/N10 -> 0.15329156 | P11: =N11/C11 -> 1667.3578 | Q11: 30745.192 | R11: =(Q11-Q10)/Q10 -> 0.15329265 | S11: =(Q11*10^9)/(C11) -> 233566.04 | U11: 7.5477036e+11 | V11: =(U11-U10)/U10 -> 0.15329156 | W11: =U11/C11 -> 5733.8631 | X11: 44.6 | Y11: 22.1 | Z11: 83.8
A12: 2003 | B12: 135310.15 | C12: =B12*1000 -> 135310147 | D12: 45.837208 | E12: =C12-F12 -> 73287753 | F12: =(D12*C12)/100 -> 62022394 | N12: 2.3560637e+11 | O12: =(N12-N11)/N11 -> 0.07347195 | P12: =N12/C12 -> 1741.2321 | Q12: 33004.796 | R12: =(Q12-Q11)/Q11 -> 0.073494557 | S12: =(Q12*10^9)/(C12) -> 243919.6 | U12: 8.1022481e+11 | V12: =(U12-U11)/U11 -> 0.07347195 | W12: =U12/C12 -> 5987.9087 | X12: 52.2 | Y12: 32.7 | Z12: 84.9
A13: 2004 | B13: 139095.14 | C13: =B13*1000 -> 139095142 | D13: 46.69948 | E13: =C13-F13 -> 74138433 | F13: =(D13*C13)/100 -> 64956709 | N13: 2.5740128e+11 | O13: =(N13-N12)/N12 -> 0.092505582 | P13: =N13/C13 -> 1850.5411 | Q13: 36057.738 | R13: =(Q13-Q12)/Q12 -> 0.092499933 | S13: =(Q13*10^9)/(C13) -> 259230.75 | U13: 8.8517513e+11 | V13: =(U13-U12)/U12 -> 0.092505582 | W13: =U13/C13 -> 6363.8105 | X13: 46.1 | Y13: 22.8 | Z13: 83.8
A14: 2005 | B14: 143018.95 | C14: =B14*1000 -> 143018948 | D14: 47.565641 | E14: =C14-F14 -> 74991068 | F14: =(D14*C14)/100 -> 68027880 | N14: 2.739741e+11 | O14: =(N14-N13)/N13 -> 0.064385165 | P14: =N14/C14 -> 1915.649 | Q14: 38378.796 | R14: =(Q14-Q13)/Q13 -> 0.064370602 | S14: =(Q14*10^9)/(C14) -> 268347.63 | U14: 9.4216727e+11 | V14: =(U14-U13)/U13 -> 0.064385165 | W14: =U14/C14 -> 6587.7094 | X14: 46.8 | Y14: 23.1 | Z14: 83.8
A15: 2006 | B15: 147015.56 | C15: =B15*1000 -> 147015559 | D15: 48.424272 | E15: =C15-F15 -> 75824345 | F15: =(D15*C15)/100 -> 71191214 | N15: 2.9057536e+11 | O15: =(N15-N14)/N14 -> 0.06059428 | P15: =N15/C15 -> 1976.494 | Q15: 40703.681 | R15: =(Q15-Q14)/Q14 -> 0.060577339 | S15: =(Q15*10^9)/(C15) -> 276866.49 | U15: 9.9925722e+11 | V15: =(U15-U14)/U14 -> 0.06059428 | W15: =U15/C15 -> 6796.9488 | X15: 47.6 | Y15: 23.5 | Z15: 83.9
A16: 2007 | B16: 151139.11 | C16: =B16*1000 -> 151139108 | D16: 49.235799 | E16: =C16-F16 -> 76724561 | F16: =(D16*C16)/100 -> 74414547 | N16: 3.0972756e+11 | O16: =(N16-N15)/N15 -> 0.065911304 | P16: =N16/C16 -> 2049.288 | Q16: 43385.877 | R16: =(Q16-Q15)/Q15 -> 0.065895654 | S16: =(Q16*10^9)/(C16) -> 287059.24 | U16: 1.0651196e+12 | V16: =(U16-U15)/U15 -> 0.065911304 | W16: =U16/C16 -> 7047.2797 | X16: 50.1 | Y16: 25.3 | Z16: 86.2
... A33: 2024 | B33: 230271.14 | C33: =B33*1000 -> 230271141 | D33: 62.975568 | E33: =C33-F33 -> 85256583 | F33: =(D33*C33)/100 -> 145014558 | N33: 5.4088602e+11 | O33: =(N33-N32)/N32 -> 0.040710665 | P33: =N33/C33 -> 2348.9093 | Q33: 79289.393 | R33: =(Q33-Q32)/Q32 -> 0.033963016 | S33: =(Q33*10^9)/(C33) -> 344330.57 | U33: 1.8600485e+12 | V33: =(U33-U32)/U32 -> 0.040710665 | W33: =U33/C33 -> 8077.6448 | X33: 62.5 | Y33: 23.5 | Z33: 85.5
A34: 2025 | B34: 235087.81 | C34: =B34*1000 -> 235087814 | D34: 63.775418 | E34: =C34-F34 -> 85159578 | F34: =(D34*C34)/100 -> 1.4992824e+08 | G34: 5.6 | H34: 6 | I34: 4.9 | K34: =C34/G34 -> 41979967 | L34: =E34/H34 -> 14193263 | M34: =F34/I34 -> 30597599 | N34: 5.6259374e+11 | O34: =(N34-N33)/N33 -> 0.040133618 | P34: =N34/C34 -> 2393.1216 | Q34: =Q33+(Q33*R34) -> 82471.563 | R34: =O34 -> 0.040133618 | S34: =(Q34*10^9)/(C34) -> 350811.73 | U34: 1.934699e+12 | V34: =(U34-U33)/U33 -> 0.040133618 | W34: =U34/C34 -> 8229.6863 | X34: =(Z34*D34+Y34*(100-D34))/100 -> 65.903705 | Y34: =IF(100/(1+EXP(-('Access Projection Model'!$T$64+'Access Projection Model'!$T$61*(A34-2024))))>=100*'Access Projection Model'!$T$62,100,100/(1+EXP(-('Access Projection Model'!$T$64+'Access Projection Model'!$T$61*(A34-2024))))) -> 27.635921 | Z34: =IF(100/(1+EXP(-('Access Projection Model'!$T$63+'Access Projection Model'!$T$60*(A34-2024))))>=100*'Access Projection Model'!$T$62,100,100/(1+EXP(-('Access Projection Model'!$T$63+'Access Projection Model'!$T$60*(A34-2024))))) -> 87.639894
A35: 2026 | B35: 239967.75 | C35: =B35*1000 -> 239967749 | D35: 64.574207 | E35: =C35-F35 -> 85010478 | F35: =(D35*C35)/100 -> 1.5495727e+08 | G35: =G34+(G34*J35) -> 5.5674442 | H35: =H34+(H34*J35) -> 5.9651188 | I35: =I34+(I34*J35) -> 4.8715137 | J35: -0.0058135336 | K35: =C35/G35 -> 43101958 | L35: =E35/H35 -> 14251263 | M35: =F35/I35 -> 31808855 | N35: =N34+(N34*O35) -> 590723421878 | O35: 0.05 | P35: =N35/C35 -> 2461.6784 | Q35: =Q34+(Q34*R35) -> 86595.141 | R35: =O35 -> 0.05 | S35: =(Q35*10^9)/(C35) -> 360861.58 | U35: =U34+(U34*V35) -> 2031433906346 | V35: 0.05 | W35: =U35/C35 -> 8465.4455 | X35: =(Z35*D35+Y35*(100-D35))/100 -> 69.200472 | Y35: =IF(100/(1+EXP(-('Access Projection Model'!$T$64+'Access Projection Model'!$T$61*(A35-2024))))>=100*'Access Projection Model'!$T$62,100,100/(1+EXP(-('Access Projection Model'!$T$64+'Access Projection Model'!$T$61*(A35-2024))))) -> 32.193426 | Z35: =IF(100/(1+EXP(-('Access Projection Model'!$T$63+'Access Projection Model'!$T$60*(A35-2024))))>=100*'Access Projection Model'!$T$62,100,100/(1+EXP(-('Access Projection Model'!$T$63+'Access Projection Model'!$T$60*(A35-2024))))) -> 89.502757
A36: 2027 | B36: 244895.92 | C36: =B36*1000 -> 244895915 | D36: 65.371914 | E36: =C36-F36 -> 84802769 | F36: =(D36*C36)/100 -> 1.6009315e+08 | G36: =G35+(G35*J36) -> 5.5350777 | H36: =H35+(H35*J36) -> 5.9304404 | I36: =I35+(I35*J36) -> 4.843193 | J36: -0.0058135336 | K36: =C36/G36 -> 44244350 | L36: =E36/H36 -> 14299574 | M36: =F36/I36 -> 33055290 | N36: =N35+(N35*O36) -> 620259592972 | O36: 0.05 | P36: =N36/C36 -> 2532.7478 | Q36: =Q35+(Q35*R36) -> 90924.898 | R36: =O36 -> 0.05 | S36: =(Q36*10^9)/(C36) -> 371279.77 | U36: =U35+(U35*V36) -> 2133005601663 | V36: 0.05 | W36: =U36/C36 -> 8709.8456 | X36: =(Z36*D36+Y36*(100-D36))/100 -> 72.415436 | Y36: =IF(100/(1+EXP(-('Access Projection Model'!$T$64+'Access Projection Model'!$T$61*(A36-2024))))>=100*'Access Projection Model'!$T$62,100,100/(1+EXP(-('Access Projection Model'!$T$64+'Access Projection Model'!$T$61*(A36-2024))))) -> 37.117013 | Z36: =IF(100/(1+EXP(-('Access Projection Model'!$T$63+'Access Projection Model'!$T$60*(A36-2024))))>=100*'Access Projection Model'!$T$62,100,100/(1+EXP(-('Access Projection Model'!$T$63+'Access Projection Model'!$T$60*(A36-2024))))) -> 91.113326
A37: 2028 | B37: 249852.61 | C37: =B37*1000 -> 249852610 | D37: 66.168518 | E37: =C37-F37 -> 84528842 | F37: =(D37*C37)/100 -> 1.6532377e+08 | G37: =G36+(G36*J37) -> 5.5028993 | H37: =H36+(H36*J37) -> 5.8959636 | I37: =I36+(I36*J37) -> 4.8150369 | J37: -0.0058135336 | K37: =C37/G37 -> 45403813 | L37: =E37/H37 -> 14336731 | M37: =F37/I37 -> 34334891 | N37: =N36+(N36*O37) -> 651272572621 | O37: 0.05 | P37: =N37/C37 -> 2606.6271 | Q37: =Q36+(Q36*R37) -> 95471.143 | R37: =O37 -> 0.05 | S37: =(Q37*10^9)/(C37) -> 382109.85 | U37: =U36+(U36*V37) -> 2239655881746 | V37: 0.05 | W37: =U37/C37 -> 8963.9083 | X37: =(Z37*D37+Y37*(100-D37))/100 -> 75.522926 | Y37: =IF(100/(1+EXP(-('Access Projection Model'!$T$64+'Access Projection Model'!$T$61*(A37-2024))))>=100*'Access Projection Model'!$T$62,100,100/(1+EXP(-('Access Projection Model'!$T$64+'Access Projection Model'!$T$61*(A37-2024))))) -> 42.323594 | Z37: =IF(100/(1+EXP(-('Access Projection Model'!$T$63+'Access Projection Model'!$T$60*(A37-2024))))>=100*'Access Projection Model'!$T$62,100,100/(1+EXP(-('Access Projection Model'!$T$63+'Access Projection Model'!$T$60*(A37-2024))))) -> 92.497503
A38: 2029 | B38: 254839.64 | C38: =B38*1000 -> 254839645 | D38: 66.963998 | E38: =C38-F38 -> 84188831 | F38: =(D38*C38)/100 -> 1.7065081e+08 | G38: =G37+(G37*J38) -> 5.470908 | H38: =H37+(H37*J38) -> 5.8616872 | I38: =I37+(I37*J38) -> 4.7870445 | J38: -0.0058135336 | K38: =C38/G38 -> 46580868 | L38: =E38/H38 -> 14362560 | M38: =F38/I38 -> 35648470 | N38: =N37+(N37*O38) -> 683836201252 | O38: 0.05 | P38: =N38/C38 -> 2683.398 | Q38: =Q37+(Q37*R38) -> 100244.7 | R38: =O38 -> 0.05 | S38: =(Q38*10^9)/(C38) -> 393363.84 | U38: =U37+(U37*V38) -> 2351638675833 | V38: 0.05 | W38: =U38/C38 -> 9227.9154 | X38: =(Z38*D38+Y38*(100-D38))/100 -> 78.492867 | Y38: =IF(100/(1+EXP(-('Access Projection Model'!$T$64+'Access Projection Model'!$T$61*(A38-2024))))>=100*'Access Projection Model'!$T$62,100,100/(1+EXP(-('Access Projection Model'!$T$64+'Access Projection Model'!$T$61*(A38-2024))))) -> 47.706441 | Z38: =IF(100/(1+EXP(-('Access Projection Model'!$T$63+'Access Projection Model'!$T$60*(A38-2024))))>=100*'Access Projection Model'!$T$62,100,100/(1+EXP(-('Access Projection Model'!$T$63+'Access Projection Model'!$T$60*(A38-2024))))) -> 93.681034
A39: 2030 | B39: 259865.63 | C39: =B39*1000 -> 259865631 | D39: 67.758333 | E39: =C39-F39 -> 83785011 | F39: =(D39*C39)/100 -> 1.7608062e+08 | G39: =G38+(G38*J39) -> 5.4391027 | H39: =H38+(H38*J39) -> 5.8276101 | I39: =I38+(I38*J39) -> 4.7592149 | J39: -0.0058135336 | K39: =C39/G39 -> 47777298 | L39: =E39/H39 -> 14377251 | M39: =F39/I39 -> 36997829 | N39: =N38+(N38*O39) -> 718028011314 | O39: 0.05 | P39: =N39/C39 -> 2763.0742 | Q39: =Q38+(Q38*R39) -> 105256.94 | R39: =O39 -> 0.05 | S39: =(Q39*10^9)/(C39) -> 405043.69 | U39: =U38+(U38*V39) -> 2469220609625 | V39: 0.05 | W39: =U39/C39 -> 9501.913 | X39: =(Z39*D39+Y39*(100-D39))/100 -> 81.293626 | Y39: =IF(100/(1+EXP(-('Access Projection Model'!$T$64+'Access Projection Model'!$T$61*(A39-2024))))>=100*'Access Projection Model'!$T$62,100,100/(1+EXP(-('Access Projection Model'!$T$64+'Access Projection Model'!$T$61*(A39-2024))))) -> 53.143098 | Z39: =IF(100/(1+EXP(-('Access Projection Model'!$T$63+'Access Projection Model'!$T$60*(A39-2024))))>=100*'Access Projection Model'!$T$62,100,100/(1+EXP(-('Access Projection Model'!$T$63+'Access Projection Model'!$T$60*(A39-2024))))) -> 94.688583
A40: 2031 | B40: 264896.31 | C40: =B40*1000 -> 264896308 | D40: 68.551504 | E40: =C40-F40 -> 83305906 | F40: =(D40*C40)/100 -> 1.815904e+08 | G40: =G39+(G39*J40) -> 5.4074823 | H40: =H39+(H39*J40) -> 5.7937311 | I40: =I39+(I39*J40) -> 4.731547 | J40: -0.0058135336 | K40: =C40/G40 -> 48986995 | L40: =E40/H40 -> 14378628 | M40: =F40/I40 -> 38378653 | N40: =N39+(N39*O40) -> 753929411880 | O40: 0.05 | P40: =N40/C40 -> 2846.1303 | Q40: =Q39+(Q39*R40) -> 110519.78 | R40: =O40 -> 0.05 | S40: =(Q40*10^9)/(C40) -> 417219.03 | U40: =U39+(U39*V40) -> 2592681640106 | V40: 0.05 | W40: =U40/C40 -> 9787.5341 | X40: =(Z40*D40+Y40*(100-D40))/100 -> 83.895551 | Y40: =IF(100/(1+EXP(-('Access Projection Model'!$T$64+'Access Projection Model'!$T$61*(A40-2024))))>=100*'Access Projection Model'!$T$62,100,100/(1+EXP(-('Access Projection Model'!$T$64+'Access Projection Model'!$T$61*(A40-2024))))) -> 58.50615 | Z40: =IF(100/(1+EXP(-('Access Projection Model'!$T$63+'Access Projection Model'!$T$60*(A40-2024))))>=100*'Access Projection Model'!$T$62,100,100/(1+EXP(-('Access Projection Model'!$T$63+'Access Projection Model'!$T$60*(A40-2024))))) -> 95.543122
A41: 2032 | B41: 269945.84 | C41: =B41*1000 -> 269945841 | D41: 69.343488 | E41: =C41-F41 -> 82755979 | F41: =(D41*C41)/100 -> 1.8718986e+08 | G41: =G40+(G40*J41) -> 5.3760457 | H41: =H40+(H40*J41) -> 5.760049 | I41: =I40+(I40*J41) -> 4.70404 | J41: -0.0058135336 | K41: =C41/G41 -> 50212713 | L41: =E41/H41 -> 14367235 | M41: =F41/I41 -> 39793425 | N41: =N40+(N40*O41) -> 791625882474 | O41: 0.05 | P41: =N41/C41 -> 2932.5359 | Q41: =Q40+(Q40*R41) -> 116045.77 | R41: =O41 -> 0.05 | S41: =(Q41*10^9)/(C41) -> 429885.38 | U41: =U40+(U40*V41) -> 2722315722111 | V41: 0.05 | W41: =U41/C41 -> 10084.674 | X41: =(Z41*D41+Y41*(100-D41))/100 -> 86.274441 | Y41: =IF(100/(1+EXP(-('Access Projection Model'!$T$64+'Access Projection Model'!$T$61*(A41-2024))))>=100*'Access Projection Model'!$T$62,100,100/(1+EXP(-('Access Projection Model'!$T$64+'Access Projection Model'!$T$61*(A41-2024))))) -> 63.674943 | Z41: =IF(100/(1+EXP(-('Access Projection Model'!$T$63+'Access Projection Model'!$T$60*(A41-2024))))>=100*'Access Projection Model'!$T$62,100,100/(1+EXP(-('Access Projection Model'!$T$63+'Access Projection Model'!$T$60*(A41-2024))))) -> 96.2656
A42: 2033 | B42: 275021.44 | C42: =B42*1000 -> 275021443 | D42: 70.134266 | E42: =C42-F42 -> 82137173 | F42: =(D42*C42)/100 -> 1.9288427e+08 | G42: =G41+(G41*J42) -> 5.3447919 | H42: =H41+(H41*J42) -> 5.7265628 | I42: =I41+(I41*J42) -> 4.6766929 | J42: -0.0058135336 | K42: =C42/G42 -> 51455968 | L42: =E42/H42 -> 14343189 | M42: =F42/I42 -> 41243732 | N42: =N41+(N41*O42) -> 831207176598 | O42: 0.05 | P42: =N42/C42 -> 3022.3359 | Q42: =Q41+(Q41*R42) -> 121848.06 | R42: =O42 -> 0.05 | S42: =(Q42*10^9)/(C42) -> 443049.31 | U42: =U41+(U41*V42) -> 2858431508217 | V42: 0.05 | W42: =U42/C42 -> 10393.486 | X42: =(Z42*D42+Y42*(100-D42))/100 -> 88.414197 | Y42: =IF(100/(1+EXP(-('Access Projection Model'!$T$64+'Access Projection Model'!$T$61*(A42-2024))))>=100*'Access Projection Model'!$T$62,100,100/(1+EXP(-('Access Projection Model'!$T$64+'Access Projection Model'!$T$61*(A42-2024))))) -> 68.546025 | Z42: =IF(100/(1+EXP(-('Access Projection Model'!$T$63+'Access Projection Model'!$T$60*(A42-2024))))>=100*'Access Projection Model'!$T$62,100,100/(1+EXP(-('Access Projection Model'!$T$63+'Access Projection Model'!$T$60*(A42-2024))))) -> 96.874791
A43: 2034 | B43: 280088.79 | C43: =B43*1000 -> 280088787 | D43: 70.923816 | E43: =C43-F43 -> 81439130 | F43: =(D43*C43)/100 -> 1.9864966e+08 | G43: =G42+(G42*J43) -> 5.3137198 | H43: =H42+(H42*J43) -> 5.6932712 | I43: =I42+(I42*J43) -> 4.6495048 | J43: -0.0058135336 | K43: =C43/G43 -> 52710492 | L43: =E43/H43 -> 14304453 | M43: =F43/I43 -> 42724906 | N43: =N42+(N42*O43) -> 872767535428 | O43: 0.05 | P43: =N43/C43 -> 3116.0388 | Q43: =Q42+(Q42*R43) -> 127940.46 | R43: =O43 -> 0.05 | S43: =(Q43*10^9)/(C43) -> 456785.38 | U43: =U42+(U42*V43) -> 3001353083628 | V43: 0.05 | W43: =U43/C43 -> 10715.72 | X43: =(Z43*D43+Y43*(100-D43))/100 -> 90.308173 | Y43: =IF(100/(1+EXP(-('Access Projection Model'!$T$64+'Access Projection Model'!$T$61*(A43-2024))))>=100*'Access Projection Model'!$T$62,100,100/(1+EXP(-('Access Projection Model'!$T$64+'Access Projection Model'!$T$61*(A43-2024))))) -> 73.040469 | Z43: =IF(100/(1+EXP(-('Access Projection Model'!$T$63+'Access Projection Model'!$T$60*(A43-2024))))>=100*'Access Projection Model'!$T$62,100,100/(1+EXP(-('Access Projection Model'!$T$63+'Access Projection Model'!$T$60*(A43-2024))))) -> 97.387303
A44: 2035 | B44: 285156.01 | C44: =B44*1000 -> 285156007 | D44: 71.712119 | E44: =C44-F44 -> 80664593 | F44: =(D44*C44)/100 -> 2.0449141e+08 | G44: =G43+(G43*J44) -> 5.2828283 | H44: =H43+(H43*J44) -> 5.6601732 | I44: =I43+(I43*J44) -> 4.6224748 | J44: -0.0058135336 | K44: =C44/G44 -> 53977905 | L44: =E44/H44 -> 14251259 | M44: =F44/I44 -> 44238514 | N44: =N43+(N43*O44) -> 916405912199 | O44: 0.05 | P44: =N44/C44 -> 3213.7002 | Q44: =Q43+(Q43*R44) -> 134337.49 | R44: =O44 -> 0.05 | S44: =(Q44*10^9)/(C44) -> 471101.72 | U44: =U43+(U43*V44) -> 3151420737809 | V44: 0.05 | W44: =U44/C44 -> 11051.567 | X44: =(Z44*D44+Y44*(100-D44))/100 -> 91.959106 | Y44: =IF(100/(1+EXP(-('Access Projection Model'!$T$64+'Access Projection Model'!$T$61*(A44-2024))))>=100*'Access Projection Model'!$T$62,100,100/(1+EXP(-('Access Projection Model'!$T$64+'Access Projection Model'!$T$61*(A44-2024))))) -> 77.107187 | Z44: =IF(100/(1+EXP(-('Access Projection Model'!$T$63+'Access Projection Model'!$T$60*(A44-2024))))>=100*'Access Projection Model'!$T$62,100,100/(1+EXP(-('Access Projection Model'!$T$63+'Access Projection Model'!$T$60*(A44-2024))))) -> 97.81766
A45: 2036 | B45: 290215.52 | C45: =B45*1000 -> 290215518 | D45: 72.499152 | E45: =C45-F45 -> 79811729 | F45: =(D45*C45)/100 -> 2.1040379e+08 | G45: =G44+(G44*J45) -> 5.2521164 | H45: =H44+(H44*J45) -> 5.6272676 | I45: =I44+(I44*J45) -> 4.5956019 | J45: -0.0058135336 | K45: =C45/G45 -> 55256871 | L45: =E45/H45 -> 14183034 | M45: =F45/I45 -> 45783729 | N45: =N44+(N44*O45) -> 962226207809 | O45: 0.05 | P45: =N45/C45 -> 3315.5574 | Q45: =Q44+(Q44*R45) -> 141054.36 | R45: =O45 -> 0.05 | S45: =(Q45*10^9)/(C45) -> 486033.14 | U45: =U44+(U44*V45) -> 3308991774700 | V45: 0.05 | W45: =U45/C45 -> 11401.843 | X45: =(Z45*D45+Y45*(100-D45))/100 -> 93.377883 | Y45: =IF(100/(1+EXP(-('Access Projection Model'!$T$64+'Access Projection Model'!$T$61*(A45-2024))))>=100*'Access Projection Model'!$T$62,100,100/(1+EXP(-('Access Projection Model'!$T$64+'Access Projection Model'!$T$61*(A45-2024))))) -> 80.722367 | Z45: =IF(100/(1+EXP(-('Access Projection Model'!$T$63+'Access Projection Model'!$T$60*(A45-2024))))>=100*'Access Projection Model'!$T$62,100,100/(1+EXP(-('Access Projection Model'!$T$63+'Access Projection Model'!$T$60*(A45-2024))))) -> 98.178455
A46: 2037 | B46: 295263.27 | C46: =B46*1000 -> 295263274 | D46: 73.284896 | E46: =C46-F46 -> 78879892 | F46: =(D46*C46)/100 -> 2.1638338e+08 | G46: =G45+(G45*J46) -> 5.221583 | H46: =H45+(H45*J46) -> 5.5945533 | I46: =I45+(I45*J46) -> 4.5688852 | J46: -0.0058135336 | K46: =C46/G46 -> 56546697 | L46: =E46/H46 -> 14099409 | M46: =F46/I46 -> 47360215 | N46: =N45+(N45*O46) -> 1010337518199 | O46: 0.05 | P46: =N46/C46 -> 3421.8191 | Q46: =Q45+(Q45*R46) -> 148107.08 | R46: =O46 -> 0.05 | S46: =(Q46*10^9)/(C46) -> 501610.23 | U46: =U45+(U45*V46) -> 3474441363435 | V46: 0.05 | W46: =U46/C46 -> 11767.266 | X46: =(Z46*D46+Y46*(100-D46))/100 -> 94.581573 | Y46: =IF(100/(1+EXP(-('Access Projection Model'!$T$64+'Access Projection Model'!$T$61*(A46-2024))))>=100*'Access Projection Model'!$T$62,100,100/(1+EXP(-('Access Projection Model'!$T$64+'Access Projection Model'!$T$61*(A46-2024))))) -> 83.885954 | Z46: =IF(100/(1+EXP(-('Access Projection Model'!$T$63+'Access Projection Model'!$T$60*(A46-2024))))>=100*'Access Projection Model'!$T$62,100,100/(1+EXP(-('Access Projection Model'!$T$63+'Access Projection Model'!$T$60*(A46-2024))))) -> 98.480529
... A69: 2060 | B69: 397911.85 | C69: =B69*1000 -> 397911853 | D69: 91.74898 | E69: =C69-F69 -> 32831785 | F69: =(D69*C69)/100 -> 3.6508007e+08 | G69: =G68+(G68*J69) -> 4.5662814 | H69: =H68+(H68*J69) -> 4.8924443 | I69: =I68+(I68*J69) -> 3.9954962 | J69: -0.0058135336 | K69: =C69/G69 -> 87141335 | L69: =E69/H69 -> 6710712 | M69: =F69/I69 -> 91372898 | N69: =N68+(N68*O69) -> 3103275688644 | O69: 0.05 | P69: =N69/C69 -> 7798.9024 | Q69: =Q68+(Q68*R69) -> 454914.41 | R69: =O69 -> 0.05 | S69: =(Q69*10^9)/(C69) -> 1143254.2 | U69: =U68+(U68*V69) -> 10671829186333 | V69: 0.05 | W69: =U69/C69 -> 26819.581 | X69: =(Z69*D69+Y69*(100-D69))/100 -> 100 | Y69: =IF(100/(1+EXP(-('Access Projection Model'!$T$64+'Access Projection Model'!$T$61*(A69-2024))))>=100*'Access Projection Model'!$T$62,100,100/(1+EXP(-('Access Projection Model'!$T$64+'Access Projection Model'!$T$61*(A69-2024))))) -> 100 | Z69: =IF(100/(1+EXP(-('Access Projection Model'!$T$63+'Access Projection Model'!$T$60*(A69-2024))))>=100*'Access Projection Model'!$T$62,100,100/(1+EXP(-('Access Projection Model'!$T$63+'Access Projection Model'!$T$60*(A69-2024))))) -> 100

Sheet CBN GDP
A1: Return to Menu
A2: Table C.1.2: Gross Domestic Product at 2010 Constant Basic Prices - Annual (₦' Billion)
A3: Activity Sector | B3: 1981 | C3: 1982 | D3: 1983 | E3: 1984 | F3: 1985 | G3: 1986 | H3: 1987 | I3: 1988 | J3: 1989 | K3: 1990 | L3: 1991 | M3: 1992 | N3: 1993 | O3: 1994 | P3: 1995 | Q3: 1996 | R3: 1997 | S3: 1998 | T3: 1999 | U3: 2000 | V3: 2001 | W3: 2002 | X3: 2003 | Y3: 2004 | Z3: 2005 | AA3: 2006 | AB3: 2007 | AC3: 2008 | AD3: 2009 | AE3: 2010 | AF3: 2011 | AG3: 2012 | AH3: 2013 | AI3: 2014 | AJ3: 2015 | AK3: 2016 | AL3: 2017 | AM3: 2018 | AN3: 2019 | AO3: 2020 1 | AP3: 2021 1 | AQ3: 2022 1 | AR3: 2023 1 | AS3: 2024 1
A4: A. AGRICULTURE | B4: 2364.3731 | C4: 2425.9609 | D4: 2409.0819 | E4: 2303.5054 | F4: 2731.0625 | G4: 2986.8354 | H4: 2891.6723 | I4: 3174.5676 | J4: 3325.9471 | K4: 3464.7163 | L4: 3590.8374 | M4: 3674.7928 | N4: 3743.6658 | O4: 3839.6754 | P4: 3977.3819 | Q4: 4133.5482 | R4: 4305.6796 | S4: 4475.2414 | T4: 4703.6437 | U4: 4840.9712 | V4: 5024.5421 | W4: 7817.0845 | X4: 8364.8321 | Y4: 8888.5734 | Z4: 9516.9915 | AA4: 10222.475 | AB4: 10958.469 | AC4: 11645.371 | AD4: 12330.326 | AE4: 13048.893 | AF4: 13429.379 | AG4: 14329.706 | AH4: 14750.523 | AI4: 15380.389 | AJ4: 15952.22 | AK4: 16607.337 | AL4: 17179.495 | AM4: 17544.148 | AN4: 17958.584 | AO4: 18348.176 | AP4: 18738.414 | AQ4: 19091.073 | AR4: 19306.49 | AS4: 19535.879
A5: 1. Crop Production | B5: 1854.7644 | C5: 1897.0789 | D5: 1842.7043 | E5: 1759.1152 | F5: 2180.9077 | G5: 2427.1007 | H5: 2329.9958 | I5: 2581.5951 | J5: 2710.6748 | K5: 2828.5896 | L5: 2955.8759 | M5: 3044.5522 | N5: 3132.8437 | O5: 3226.8296 | P5: 3336.5414 | Q5: 3462.996 | R5: 3611.9053 | S5: 3752.7696 | T5: 3949.4152 | U5: 4067.8976 | V5: 4222.4774 | W5: 6977.8788 | X5: 7493.0242 | Y5: 7956.6551 | Z5: 8524.1469 | AA5: 9162.6503 | AB5: 9826.7691 | AC5: 10437.994 | AD5: 11046.156 | AE5: 11683.896 | AF5: 12017.192 | AG5: 12919.542 | AH5: 13247.802 | AI5: 13793.45 | AJ5: 14274.937 | AK5: 14894.448 | AL5: 15437.05 | AM5: 15786.438 | AN5: 16181.993 | AO5: 16544.521 | AP5: 16920.524 | AQ5: 17260.752 | AR5: 17585.429 | AS5: 17865.59
A6: 2. Livestock | B6: 341.4115 | C6: 361.1157 | D6: 393.13101 | E6: 399.68538 | F6: 428.10285 | G6: 421.62797 | H6: 433.43352 | I6: 444.26994 | J6: 453.15559 | K6: 462.21899 | L6: 454.82321 | M6: 458.91679 | N6: 461.67056 | O6: 466.28756 | P6: 485.87207 | Q6: 499.96245 | R6: 512.46113 | S6: 526.29784 | T6: 541.03401 | U6: 553.47821 | V6: 570.08286 | W6: 597.49838 | X6: 622.55931 | Y6: 663.02591 | Z6: 707.87101 | AA6: 756.73419 | AB6: 809.16494 | AC6: 864.18816 | AD6: 920.19922 | AE6: 979.56405 | AF6: 999.40404 | AG6: 972.76279 | AH6: 1030.9373 | AI6: 1086.847 | AJ6: 1151.3234 | AK6: 1185.1184 | AL6: 1204.2052 | AM6: 1208.128 | AN6: 1210.0554 | AO6: 1233.1148 | AP6: 1240.2154 | AQ6: 1247.7194 | AR6: 1140.2358 | AS6: 1087.3139
A7: 3. Forestry | B7: 77.897986 | C7: 73.91025 | D7: 75.282779 | E7: 76.694141 | F7: 78.082446 | G7: 86.594916 | H7: 87.594277 | I7: 88.907948 | J7: 67.307306 | K7: 72.613568 | L7: 74.791896 | M7: 76.512108 | N7: 78.042399 | O7: 80.07146 | P7: 81.832932 | Q7: 82.2419 | R7: 82.982167 | S7: 83.977888 | T7: 85.070086 | U7: 86.346137 | V7: 88.072904 | W7: 88.690223 | X7: 90.021497 | Y7: 95.873021 | Z7: 101.5468 | AA7: 107.65807 | AB7: 114.24934 | AC7: 121.21855 | AD7: 128.31312 | AE7: 135.7209 | AF7: 142.45938 | AG7: 146.09408 | AH7: 154.31417 | AI7: 161.3382 | AJ7: 167.25841 | AK7: 171.64265 | AL7: 177.32697 | AM7: 182.74793 | AN7: 187.47487 | AO7: 190.50805 | AP7: 193.22432 | AQ7: 196.35719 | AR7: 199.82663 | AS7: 204.67885
A8: 4. Fishing | B8: 90.299226 | C8: 93.856084 | D8: 97.963819 | E8: 68.010739 | F8: 43.969459 | G8: 51.511833 | H8: 40.648692 | I8: 59.794672 | J8: 94.809388 | K8: 101.29412 | L8: 105.34641 | M8: 94.811773 | N8: 71.109128 | O8: 66.486882 | P8: 73.135571 | Q8: 88.347903 | R8: 98.331071 | S8: 112.19602 | T8: 128.12437 | U8: 133.2492 | V8: 143.90893 | W8: 153.0171 | X8: 159.2271 | Y8: 173.0194 | Z8: 183.42685 | AA8: 195.43246 | AB8: 208.28576 | AC8: 221.97014 | AD8: 235.65762 | AE8: 249.71148 | AF8: 270.32335 | AG8: 291.30671 | AH8: 317.46991 | AI8: 338.75412 | AJ8: 358.70161 | AK8: 356.12842 | AL8: 360.91336 | AM8: 366.83408 | AN8: 379.06048 | AO8: 380.03251 | AP8: 384.45087 | AQ8: 386.2438 | AR8: 380.99875 | AS8: 378.29605
A9: B. INDUSTRY | B9: 11753.403 | C9: 10189.096 | D9: 8255.7605 | E9: 8392.2459 | F9: 8768.2972 | G9: 8347.5343 | H9: 8799.3758 | I9: 9514.8051 | J9: 9442.8273 | K9: 11148.101 | L9: 10910.564 | M9: 11578.982 | N9: 10790.306 | O9: 10151.697 | P9: 9845.9737 | Q9: 10402.188 | R9: 10599.699 | S9: 10641.264 | T9: 10201.812 | U9: 10962.843 | V9: 11576.315 | W9: 11725.425 | X9: 13151.226 | Y9: 13382.862 | Z9: 13609.76 | AA9: 13342.47 | AB9: 13085.267 | AC9: 12817.786 | AD9: 13138.946 | AE9: 13826.434 | AF9: 14986.622 | AG9: 15350.452 | AH9: 15682.465 | AI9: 16742.153 | AJ9: 16366.657 | AK9: 14918.147 | AL9: 15238.28 | AM9: 15523.428 | AN9: 15882.346 | AO9: 14953.715 | AP9: 14883.774 | AQ9: 14195.583 | AR9: 14298.466 | AS9: 14648.105
A10: 1. Mining and Quarrying | B10: 5044.5534 | C10: 4507.9341 | D10: 4096.9925 | E10: 4602.2746 | F10: 4962.8116 | G10: 4860.7452 | H10: 4737.2294 | I10: 4856.7296 | J10: 5435.6683 | K10: 6860.853 | L10: 6265.2957 | M10: 6411.864 | N10: 6415.3831 | O10: 6246.6722 | P10: 6393.0531 | Q10: 6850.3721 | R10: 6952.0856 | S10: 7103.3848 | T10: 6572.8941 | U10: 7302.9885 | V10: 7685.3722 | W10: 7247.857 | X10: 8975.8121 | Y10: 9275.1444 | Z10: 9323.7508 | AA10: 8907.4688 | AB10: 8508.8216 | AC10: 7989.1874 | AD10: 8030.0101 | AE10: 8454.5542 | AF10: 8658.0549 | AG10: 8244.3861 | AH10: 7188.1515 | AI10: 7107.0296 | AJ10: 6732.5076 | AK10: 5759.8167 | AL10: 6025.78 | AM10: 6092.4771 | AN10: 6362.6308 | AO10: 5819.3912 | AP10: 5366.1934 | AQ10: 4391.4247 | AR10: 4266.505 | AS10: 4473.2374
A11: a. Crude Petroleum and Natural Gas | B11: 4977.4167 | C11: 4453.0936 | D11: 4052.9777 | E11: 4559.1962 | F11: 4918.2725 | G11: 4825.4975 | H11: 4704.4234 | I11: 4828.6823 | J11: 5407.0095 | K11: 6831.7677 | L11: 6224.4521 | M11: 6381.2596 | N11: 6394.6026 | O11: 6229.4586 | P11: 6375.9706 | Q11: 6832.8367 | R11: 6933.581 | S11: 7083.9876 | T11: 6552.6885 | U11: 7281.9439 | V11: 7662.9799 | W11: 7225.6782 | X11: 8952.6152 | Y11: 9248.0516 | Z11: 9294.0514 | AA11: 8874.6999 | AB11: 8471.9483 | AC11: 7947.7183 | AD11: 7983.628 | AE11: 8402.6764 | AF11: 8598.6366 | AG11: 8173.2558 | AH11: 7105.2834 | AI11: 7011.8148 | AJ11: 6629.9637 | AK11: 5672.207 | AL11: 5938.0477 | AM11: 5995.8751 | AN11: 6270.8592 | AO11: 5713.1959 | AP11: 5239.0544 | AQ11: 4231.9034 | AR11: 4138.1595 | AS11: 4367.2429
A12: b. Coal Mining | B12: 21.325684 | C12: 10.288707 | D12: 9.7275049 | E12: 14.030055 | F12: 26.189436 | G12: 26.189436 | H12: 21.512751 | I12: 15.526594 | J12: 15.339527 | K12: 15.526594 | L12: 27.498908 | M12: 17.397268 | N12: 6.9214939 | O12: 2.806011 | P12: 2.2448088 | Q12: 2.4318762 | R12: 2.6189436 | S12: 2.6189436 | T12: 2.806011 | U12: 2.9930784 | V12: 2.7299507 | W12: 1.7062192 | X12: 1.7062192 | Y12: 1.8768411 | Z12: 2.0645252 | AA12: 2.2709777 | AB12: 2.4979729 | AC12: 2.7173227 | AD12: 2.9578536 | AE12: 3.2182308 | AF12: 3.8746935 | AG12: 4.5766328 | AH12: 5.496764 | AI12: 6.5876954 | AJ12: 7.2720548 | AK12: 7.344651 | AL12: 7.2380044 | AM12: 6.8172272 | AN12: 7.7136321 | AO12: 6.1326912 | AP12: 7.711697 | AQ12: 8.1930194 | AR12: 7.2454705 | AS12: 2.4934158
A13: c. Metal Ores | B13: 7.8629668 | C13: 5.8709112 | D13: 4.8222558 | E13: 3.6839383 | F13: 2.670368 | G13: 0.62373559 | H13: 2.0739208 | I13: 2.3623985 | J13: 2.4091787 | K13: 2.1440911 | L13: 1.4735753 | M13: 0.87322983 | N13: 0.90831495 | O13: 1.0681472 | P13: 1.1383175 | Q13: 1.2396745 | R13: 1.1344191 | S13: 1.1422158 | T13: 1.1695042 | U13: 1.2045894 | V13: 1.1307147 | W13: 1.1360483 | X13: 1.0933798 | Y13: 1.212496 | Z13: 1.344658 | AA13: 1.5087905 | AB13: 1.6898649 | AC13: 1.8923084 | AD13: 2.1102071 | AE13: 2.3548433 | AF13: 2.7069689 | AG13: 2.8895836 | AH13: 3.3266386 | AI13: 3.8789393 | AJ13: 4.1609185 | AK13: 5.0237911 | AL13: 6.0971395 | AM13: 7.7029001 | AN13: 6.5952748 | AO13: 6.2095552 | AP13: 8.3324859 | AQ13: 9.6642834 | AR13: 14.527388 | AS13: 25.456839
A14: d. Quarrying and Other Minerals | B14: 37.948075 | C14: 38.68088 | D14: 29.465082 | E14: 25.364374 | F14: 15.679282 | G14: 8.4345213 | H14: 9.2193227 | I14: 10.158352 | J14: 10.910105 | K14: 11.414651 | L14: 11.871167 | M14: 12.333852 | N14: 12.950764 | O14: 13.33942 | P14: 13.699432 | Q14: 13.863796 | R14: 14.751269 | S14: 15.636098 | T14: 16.230097 | U14: 16.84701 | V14: 18.531668 | W14: 19.336556 | X14: 20.397323 | Y14: 24.003459 | Z14: 26.29023 | AA14: 28.989077 | AB14: 32.68546 | AC14: 36.859397 | AD14: 41.314096 | AE14: 46.304721 | AF14: 52.836612 | AG14: 63.664043 | AH14: 74.04472 | AI14: 84.748233 | AJ14: 91.110835 | AK14: 75.241299 | AL14: 74.397174 | AM14: 82.081898 | AN14: 77.462696 | AO14: 93.853104 | AP14: 111.09485 | AQ14: 141.66402 | AR14: 106.57264 | AS14: 78.044271
A15: 2. Manufacturing | B15: 5838.8944 | C15: 4984.7868 | D15: 3537.7226 | E15: 3282.5172 | F15: 3453.7168 | G15: 3137.5088 | H15: 3680.7137 | I15: 4237.7956 | J15: 3568.6866 | K15: 3825.609 | L15: 4165.392 | M15: 4667.7568 | N15: 3850.4106 | O15: 3364.5685 | P15: 2898.4743 | Q15: 2990.6887 | R15: 3051.9108 | S15: 2908.2138 | T15: 2975.6152 | U15: 2980.6517 | V15: 3050.5051 | W15: 3591.4021 | X15: 3203.242 | Y15: 3169.2111 | Z15: 3242.1968 | AA15: 3268.5501 | AB15: 3271.6545 | AC15: 3369.7125 | AD15: 3491.2935 | AE15: 3578.6417 | AF15: 4216.1913 | AG15: 4783.6594 | AH15: 5826.3584 | AI15: 6684.2177 | AJ15: 6586.6186 | AK15: 6302.2324 | AL15: 6288.8968 | AM15: 6420.5903 | AN15: 6469.8319 | AO15: 6291.5921 | AP15: 6502.2576 | AQ15: 6661.3918 | AR15: 6754.9593 | AS15: 6848.4613
... A62: GDP at 2010 Constant Market Prices | B62: 19748.534 | C62: 18404.965 | D62: 16394.391 | E62: 16211.491 | F62: 17170.081 | G62: 17180.545 | H62: 17730.344 | I62: 19030.692 | J62: 19395.964 | K62: 21680.205 | L62: 21757.896 | M62: 22765.546 | N62: 22302.24 | O62: 21897.472 | P62: 21881.56 | Q62: 22799.693 | R62: 23469.343 | S62: 24075.146 | T62: 24215.776 | U62: 25430.423 | V62: 26935.316 | W62: 31064.272 | X62: 33346.625 | Y62: 36431.374 | Z62: 38777.014 | AA62: 41126.679 | AB62: 43837.392 | AC62: 46802.76 | AD62: 50564.263 | AE62: 55469.35 | AF62: 58180.352 | AG62: 60670.05 | AH62: 63942.846 | AI62: 67977.459 | AJ62: 69780.693 | AK62: 68652.43 | AL62: 69205.691 | AM62: 70536.349 | AN62: 72094.094 | AO62: 70800.543 | AP62: 73382.771 | AQ62: 74752.417 | AR62: 77936.1 | AS62: 80606.533
A63: Source: National Bureau of Statistics
A64: Note 1Provisional

Sheet Access Projection Model
B2: Projection of Urban & Rural Electricity Access, 2025-2060
B4: Drivers used (1) INCOME/AFFORDABILITY - access in each segment is a logistic function of GDP per capita in constant 2015 US, fitted by OLS on the logit transform: ln(a/(1-a)) = intercept + slope x ln(GDP pc). (2) URBANIZATION/DENSITY - national access is the urbanization-weighted average of the two segment curves, so rural-to-urban migration mechanically raises national access (the composition effect). Other drivers - utility finances, policy programs, off-grid cost declines - are captured implicitly in the fitted elasticities and noted under caveats.
B10: FITTED PARAMETERS (estimation sample 1995-2024, n=30)
B13: Year | C13: GDP pc (2015 US$) | D13: ln(GDP pc) | E13: Urban access (actual) | F13: logit(urban) | G13: Rural access (actual) | H13: logit(rural) | J13: PARAMETERS | S13: RURAL MODEL: OUT-OF-SAMPLE BACKCAST
B14: ='Macro-Economic_Demographic Data'!A4 -> 1995 | C14: ='Macro-Economic_Demographic Data'!P4 -> 1413.597 | D14: =LN(C14) -> 7.2538928 | E14: ='Macro-Economic_Demographic Data'!Z4/100 -> 0.84004929 | F14: =LN(E14/(1-E14)) -> 1.6585948 | G14: ='Macro-Economic_Demographic Data'!Y4/100 -> 0.17159768 | H14: =LN(G14/(1-G14)) -> -1.5743462 | J14: Urban: slope on ln(GDP pc) | L14: =SLOPE(F14:F43,D14:D43) -> 0.099639473 | S14: Slope fitted on 1995-2014 only | T14: =SLOPE(H14:H33,D14:D33) -> 0.76120088
B15: ='Macro-Economic_Demographic Data'!A5 -> 1996 | C15: ='Macro-Economic_Demographic Data'!P5 -> 1434.8111 | D15: =LN(C15) -> 7.2687885 | E15: ='Macro-Economic_Demographic Data'!Z5/100 -> 0.84036476 | F15: =LN(E15/(1-E15)) -> 1.6609446 | G15: ='Macro-Economic_Demographic Data'!Y5/100 -> 0.17903206 | H15: =LN(G15/(1-G15)) -> -1.5229192 | J15: Urban: intercept | L15: =INTERCEPT(F14:F43,D14:D43) -> 0.94663698 | S15: Intercept fitted on 1995-2014 only | T15: =INTERCEPT(H14:H33,D14:D33) -> -6.8923904
B16: ='Macro-Economic_Demographic Data'!A6 -> 1997 | C16: ='Macro-Economic_Demographic Data'!P6 -> 1438.9313 | D16: =LN(C16) -> 7.2716559 | E16: ='Macro-Economic_Demographic Data'!Z6/100 -> 0.84052223 | F16: =LN(E16/(1-E16)) -> 1.6621189 | G16: ='Macro-Economic_Demographic Data'!Y6/100 -> 0.18658547 | H16: =LN(G16/(1-G16)) -> -1.4723514 | J16: Urban: R-squared (logit space) | L16: =RSQ(F14:F43,D14:D43) -> 0.020952796
B17: ='Macro-Economic_Demographic Data'!A7 -> 1998 | C17: ='Macro-Economic_Demographic Data'!P7 -> 1438.2156 | D17: =LN(C17) -> 7.2711584 | E17: ='Macro-Economic_Demographic Data'!Z7/100 -> 0.84049019 | F17: =LN(E17/(1-E17)) -> 1.6618798 | G17: ='Macro-Economic_Demographic Data'!Y7/100 -> 0.19425149 | H17: =LN(G17/(1-G17)) -> -1.422618 | J17: Rural: slope on ln(GDP pc) | L17: =SLOPE(H14:H43,D14:D43) -> 0.73659986 | S17: Year | T17: Predicted rural (%) | U17: Actual rural (%) | V17: Abs error (pp)
B18: ='Macro-Economic_Demographic Data'!A8 -> 1999 | C18: ='Macro-Economic_Demographic Data'!P8 -> 1409.0931 | D18: =LN(C18) -> 7.2507016 | E18: ='Macro-Economic_Demographic Data'!Z8/100 -> 0.843 | F18: =LN(E18/(1-E18)) -> 1.6807212 | G18: ='Macro-Economic_Demographic Data'!Y8/100 -> 0.2432679 | H18: =LN(G18/(1-G18)) -> -1.134846 | J18: Rural: intercept | L18: =INTERCEPT(H14:H43,D14:D43) -> -6.7100885 | S18: =B34 -> 2015 | T18: =100/(1+EXP(-($T$15+$T$14*D34))) -> 28.872196 | U18: =G34*100 -> 25.9 | V18: =ABS(T18-U18) -> 2.972196
B19: ='Macro-Economic_Demographic Data'!A9 -> 2000 | C19: ='Macro-Economic_Demographic Data'!P9 -> 1441.1664 | D19: =LN(C19) -> 7.2732081 | E19: ='Macro-Economic_Demographic Data'!Z9/100 -> 0.838 | F19: =LN(E19/(1-E19)) -> 1.6434218 | G19: ='Macro-Economic_Demographic Data'!Y9/100 -> 0.215 | H19: =LN(G19/(1-G19)) -> -1.2950457 | J19: Rural: R-squared (logit space) | L19: =RSQ(H14:H43,D14:D43) -> 0.47284606 | S19: =B35 -> 2016 | T19: =100/(1+EXP(-($T$15+$T$14*D35))) -> 28.235718 | U19: =G35*100 -> 34 | V19: =ABS(T19-U19) -> 5.7642818
B20: ='Macro-Economic_Demographic Data'!A10 -> 2001 | C20: ='Macro-Economic_Demographic Data'!P10 -> 1485.7214 | D20: =LN(C20) -> 7.3036557 | E20: ='Macro-Economic_Demographic Data'!Z10/100 -> 0.838 | F20: =LN(E20/(1-E20)) -> 1.6434218 | G20: ='Macro-Economic_Demographic Data'!Y10/100 -> 0.218 | H20: =LN(G20/(1-G20)) -> -1.2773597 | S20: =B36 -> 2017 | T20: =100/(1+EXP(-($T$15+$T$14*D36))) -> 27.978501 | U20: =G36*100 -> 22.6 | V20: =ABS(T20-U20) -> 5.3785012
B21: ='Macro-Economic_Demographic Data'!A11 -> 2002 | C21: ='Macro-Economic_Demographic Data'!P11 -> 1667.3578 | D21: =LN(C21) -> 7.4189955 | E21: ='Macro-Economic_Demographic Data'!Z11/100 -> 0.838 | F21: =LN(E21/(1-E21)) -> 1.6434218 | G21: ='Macro-Economic_Demographic Data'!Y11/100 -> 0.221 | H21: =LN(G21/(1-G21)) -> -1.2598483 | J21: Interpretation: rural access is arguably income-driven (R2 ~ 0.47). Urban access history is flat (R2 ~ 0.02), so the urban projection instead uses the cross-country panel calibration on the 'Urban Panel' sheet: Nigeria's negative country effect (-1.13 logit) decays with a 12-year half-life toward the international income norm | S21: =B37 -> 2018 | T21: =100/(1+EXP(-($T$15+$T$14*D37))) -> 27.904162 | U21: =G37*100 -> 31 | V21: =ABS(T21-U21) -> 3.0958375
B22: ='Macro-Economic_Demographic Data'!A12 -> 2003 | C22: ='Macro-Economic_Demographic Data'!P12 -> 1741.2321 | D22: =LN(C22) -> 7.4623482 | E22: ='Macro-Economic_Demographic Data'!Z12/100 -> 0.849 | F22: =LN(E22/(1-E22)) -> 1.7267793 | G22: ='Macro-Economic_Demographic Data'!Y12/100 -> 0.327 | H22: =LN(G22/(1-G22)) -> -0.72178516 | S22: =B38 -> 2019 | T22: =100/(1+EXP(-($T$15+$T$14*D38))) -> 27.896175 | U22: =G38*100 -> 25.5 | V22: =ABS(T22-U22) -> 2.3961746
B23: ='Macro-Economic_Demographic Data'!A13 -> 2004 | C23: ='Macro-Economic_Demographic Data'!P13 -> 1850.5411 | D23: =LN(C23) -> 7.5232334 | E23: ='Macro-Economic_Demographic Data'!Z13/100 -> 0.838 | F23: =LN(E23/(1-E23)) -> 1.6434218 | G23: ='Macro-Economic_Demographic Data'!Y13/100 -> 0.228 | H23: =LN(G23/(1-G23)) -> -1.2196389 | S23: =B39 -> 2020 | T23: =100/(1+EXP(-($T$15+$T$14*D39))) -> 26.578774 | U23: =G39*100 -> 24.6 | V23: =ABS(T23-U23) -> 1.9787737
B24: ='Macro-Economic_Demographic Data'!A14 -> 2005 | C24: ='Macro-Economic_Demographic Data'!P14 -> 1915.649 | D24: =LN(C24) -> 7.5578117 | E24: ='Macro-Economic_Demographic Data'!Z14/100 -> 0.838 | F24: =LN(E24/(1-E24)) -> 1.6434218 | G24: ='Macro-Economic_Demographic Data'!Y14/100 -> 0.231 | H24: =LN(G24/(1-G24)) -> -1.2026733 | S24: =B40 -> 2021 | T24: =100/(1+EXP(-($T$15+$T$14*D40))) -> 26.429788 | U24: =G40*100 -> 26.3 | V24: =ABS(T24-U24) -> 0.12978793
B25: ='Macro-Economic_Demographic Data'!A15 -> 2006 | C25: ='Macro-Economic_Demographic Data'!P15 -> 1976.494 | D25: =LN(C25) -> 7.5890798 | E25: ='Macro-Economic_Demographic Data'!Z15/100 -> 0.839 | F25: =LN(E25/(1-E25)) -> 1.6508063 | G25: ='Macro-Economic_Demographic Data'!Y15/100 -> 0.235 | H25: =LN(G25/(1-G25)) -> -1.1802903 | S25: =B41 -> 2022 | T25: =100/(1+EXP(-($T$15+$T$14*D41))) -> 26.748264 | U25: =G41*100 -> 27 | V25: =ABS(T25-U25) -> 0.25173636
B26: ='Macro-Economic_Demographic Data'!A16 -> 2007 | C26: ='Macro-Economic_Demographic Data'!P16 -> 2049.288 | D26: =LN(C26) -> 7.6252477 | E26: ='Macro-Economic_Demographic Data'!Z16/100 -> 0.862 | F26: =LN(E26/(1-E26)) -> 1.8320016 | G26: ='Macro-Economic_Demographic Data'!Y16/100 -> 0.253 | H26: =LN(G26/(1-G26)) -> -1.0826757 | S26: =B42 -> 2023 | T26: =100/(1+EXP(-($T$15+$T$14*D42))) -> 26.92183 | U26: =G42*100 -> 32.9 | V26: =ABS(T26-U26) -> 5.97817
B27: ='Macro-Economic_Demographic Data'!A17 -> 2008 | C27: ='Macro-Economic_Demographic Data'!P17 -> 2127.9843 | D27: =LN(C27) -> 7.6629305 | E27: ='Macro-Economic_Demographic Data'!Z17/100 -> 0.848 | F27: =LN(E27/(1-E27)) -> 1.7190001 | G27: ='Macro-Economic_Demographic Data'!Y17/100 -> 0.256 | H27: =LN(G27/(1-G27)) -> -1.0668636 | S27: =B43 -> 2024 | T27: =100/(1+EXP(-($T$15+$T$14*D43))) -> 27.206463 | U27: =G43*100 -> 23.5 | V27: =ABS(T27-U27) -> 3.7064627
B28: ='Macro-Economic_Demographic Data'!A18 -> 2009 | C28: ='Macro-Economic_Demographic Data'!P18 -> 2235.7163 | D28: =LN(C28) -> 7.712317 | E28: ='Macro-Economic_Demographic Data'!Z18/100 -> 0.841 | F28: =LN(E28/(1-E28)) -> 1.6656875 | G28: ='Macro-Economic_Demographic Data'!Y18/100 -> 0.246 | H28: =LN(G28/(1-G28)) -> -1.1200608 | S28: Mean absolute error, 2015-2024 (pp) | T28: =AVERAGE(V18:V27) -> 3.1651922
B29: ='Macro-Economic_Demographic Data'!A19 -> 2010 | C29: ='Macro-Economic_Demographic Data'!P19 -> 2348.4232 | D29: =LN(C29) -> 7.7614994 | E29: ='Macro-Economic_Demographic Data'!Z19/100 -> 0.798 | F29: =LN(E29/(1-E29)) -> 1.3738409 | G29: ='Macro-Economic_Demographic Data'!Y19/100 -> 0.235 | H29: =LN(G29/(1-G29)) -> -1.1802903
B30: ='Macro-Economic_Demographic Data'!A20 -> 2011 | C30: ='Macro-Economic_Demographic Data'!P20 -> 2404.6249 | D30: =LN(C30) -> 7.7851492 | E30: ='Macro-Economic_Demographic Data'!Z20/100 -> 0.871 | F30: =LN(E30/(1-E30)) -> 1.9098296 | G30: ='Macro-Economic_Demographic Data'!Y20/100 -> 0.31 | H30: =LN(G30/(1-G30)) -> -0.8001193 | J30: SOURCES | S30: RURAL MODEL: 95% CONFIDENCE INTERVAL ON INCOME ELASTICITY
B31: ='Macro-Economic_Demographic Data'!A21 -> 2012 | C31: ='Macro-Economic_Demographic Data'!P21 -> 2437.1667 | D31: =LN(C31) -> 7.7985915 | E31: ='Macro-Economic_Demographic Data'!Z21/100 -> 0.845 | F31: =LN(E31/(1-E31)) -> 1.6959115 | G31: ='Macro-Economic_Demographic Data'!Y21/100 -> 0.27 | H31: =LN(G31/(1-G31)) -> -0.99462258 | J31: Historical urban/rural/national access 1995-2024: World Bank WDI https://data.worldbank.org/indicator/EG.ELC.ACCS.ZS?locations=NG | S31: Standard error of slope (full sample) | T31: =STEYX(H14:H43,D14:D43)/SQRT(DEVSQ(D14:D43)) -> 0.14698109
B32: ='Macro-Economic_Demographic Data'!A22 -> 2013 | C32: ='Macro-Economic_Demographic Data'!P22 -> 2529.2309 | D32: =LN(C32) -> 7.8356706 | E32: ='Macro-Economic_Demographic Data'!Z22/100 -> 0.836 | F32: =LN(E32/(1-E32)) -> 1.6287622 | G32: ='Macro-Economic_Demographic Data'!Y22/100 -> 0.316 | H32: =LN(G32/(1-G32)) -> -0.7722157 | J32: GDP per capita, constant 2015 US$ | S32: t-value (df=28, 95%) | T32: =(_xlfn.T.INV.2T(0.05, COUNT(H14:H43)-2)) -> 2.0484071
B33: ='Macro-Economic_Demographic Data'!A23 -> 2014 | C33: ='Macro-Economic_Demographic Data'!P23 -> 2617.7146 | D33: =LN(C33) -> 7.8700569 | E33: ='Macro-Economic_Demographic Data'!Z23/100 -> 0.847 | F33: =LN(E33/(1-E33)) -> 1.7112628 | G33: ='Macro-Economic_Demographic Data'!Y23/100 -> 0.271 | H33: =LN(G33/(1-G33)) -> -0.98955491 | S33: Slope lower / central / upper | T33: =L17-T32*T31 -> 0.43552275
B34: ='Macro-Economic_Demographic Data'!A24 -> 2015 | C34: ='Macro-Economic_Demographic Data'!P24 -> 2618.0476 | D34: =LN(C34) -> 7.8701841 | E34: ='Macro-Economic_Demographic Data'!Z24/100 -> 0.815 | F34: =LN(E34/(1-E34)) -> 1.4828323 | G34: ='Macro-Economic_Demographic Data'!Y24/100 -> 0.259 | H34: =LN(G34/(1-G34)) -> -1.0511726 | S34: (central) | T34: =L17 -> 0.73659986
B35: ='Macro-Economic_Demographic Data'!A25 -> 2016 | C35: ='Macro-Economic_Demographic Data'!P25 -> 2512.9094 | D35: =LN(C35) -> 7.8291965 | E35: ='Macro-Economic_Demographic Data'!Z25/100 -> 0.86 | F35: =LN(E35/(1-E35)) -> 1.81529 | G35: ='Macro-Economic_Demographic Data'!Y25/100 -> 0.34 | H35: =LN(G35/(1-G35)) -> -0.66329422 | S35: (upper) | T35: =L17+T32*T31 -> 1.037677
B36: ='Macro-Economic_Demographic Data'!A26 -> 2017 | C36: ='Macro-Economic_Demographic Data'!P26 -> 2471.2367 | D36: =LN(C36) -> 7.812474 | E36: ='Macro-Economic_Demographic Data'!Z26/100 -> 0.868 | F36: =LN(E36/(1-E36)) -> 1.8833898 | G36: ='Macro-Economic_Demographic Data'!Y26/100 -> 0.226 | H36: =LN(G36/(1-G36)) -> -1.2310369 | S36: Rural access 2060 - lower (%) | T36: =100/(1+EXP(-((AVERAGE(H14:H43)-T33*AVERAGE(D14:D43))+T33*LN('Macro-Economic_Demographic Data'!P69)))) -> 37.379402
B37: ='Macro-Economic_Demographic Data'!A27 -> 2018 | C37: ='Macro-Economic_Demographic Data'!P27 -> 2459.2791 | D37: =LN(C37) -> 7.8076235 | E37: ='Macro-Economic_Demographic Data'!Z27/100 -> 0.817 | F37: =LN(E37/(1-E37)) -> 1.4961529 | G37: ='Macro-Economic_Demographic Data'!Y27/100 -> 0.31 | H37: =LN(G37/(1-G37)) -> -0.8001193 | S37: Rural access 2060 - central (%) | T37: =100/(1+EXP(-((AVERAGE(H14:H43)-T34*AVERAGE(D14:D43))+T34*LN('Macro-Economic_Demographic Data'!P69)))) -> 47.280854
B38: ='Macro-Economic_Demographic Data'!A28 -> 2019 | C38: ='Macro-Economic_Demographic Data'!P28 -> 2457.9965 | D38: =LN(C38) -> 7.8071019 | E38: ='Macro-Economic_Demographic Data'!Z28/100 -> 0.839 | F38: =LN(E38/(1-E38)) -> 1.6508063 | G38: ='Macro-Economic_Demographic Data'!Y28/100 -> 0.255 | H38: =LN(G38/(1-G38)) -> -1.0721207 | S38: Rural access 2060 - upper (%) | T38: =100/(1+EXP(-((AVERAGE(H14:H43)-T35*AVERAGE(D14:D43))+T35*LN('Macro-Economic_Demographic Data'!P69)))) -> 57.400926
B39: ='Macro-Economic_Demographic Data'!A29 -> 2020 | C39: ='Macro-Economic_Demographic Data'!P29 -> 2252.4251 | D39: =LN(C39) -> 7.7197627 | E39: ='Macro-Economic_Demographic Data'!Z29/100 -> 0.839 | F39: =LN(E39/(1-E39)) -> 1.6508063 | G39: ='Macro-Economic_Demographic Data'!Y29/100 -> 0.246 | H39: =LN(G39/(1-G39)) -> -1.1200608
B40: ='Macro-Economic_Demographic Data'!A30 -> 2021 | C40: ='Macro-Economic_Demographic Data'!P30 -> 2229.9066 | D40: =LN(C40) -> 7.709715 | E40: ='Macro-Economic_Demographic Data'!Z30/100 -> 0.892 | F40: =LN(E40/(1-E40)) -> 2.1113349 | G40: ='Macro-Economic_Demographic Data'!Y30/100 -> 0.263 | H40: =LN(G40/(1-G40)) -> -1.0304339 | S40: Rural approach model passes out-of-sample validation - fitted on 1995-2014 it predicts 2015-2024 within ~3 pp MAE, and rural access, unlike urban, is far from any ceiling, so convergence dynamics matter less before 2060. The 95% CI fan brackets the 2060 stimate. Caveat: the fit embeds historical grid economics; the collapsing cost of solar home systems and mini-grids (e.g. World Bank DARES) is an upside risk, so the projection path should be read as conservative.
B41: ='Macro-Economic_Demographic Data'!A31 -> 2022 | C41: ='Macro-Economic_Demographic Data'!P31 -> 2278.22 | D41: =LN(C41) -> 7.7311497 | E41: ='Macro-Economic_Demographic Data'!Z31/100 -> 0.89 | F41: =LN(E41/(1-E41)) -> 2.0907411 | G41: ='Macro-Economic_Demographic Data'!Y31/100 -> 0.27 | H41: =LN(G41/(1-G41)) -> -0.99462258
B42: ='Macro-Economic_Demographic Data'!A32 -> 2023 | C42: ='Macro-Economic_Demographic Data'!P32 -> 2304.8322 | D42: =LN(C42) -> 7.7427632 | E42: ='Macro-Economic_Demographic Data'!Z32/100 -> 0.85 | F42: =LN(E42/(1-E42)) -> 1.7346011 | G42: ='Macro-Economic_Demographic Data'!Y32/100 -> 0.329 | H42: =LN(G42/(1-G42)) -> -0.71271139
B43: ='Macro-Economic_Demographic Data'!A33 -> 2024 | C43: ='Macro-Economic_Demographic Data'!P33 -> 2348.9093 | D43: =LN(C43) -> 7.7617064 | E43: ='Macro-Economic_Demographic Data'!Z33/100 -> 0.855 | F43: =LN(E43/(1-E43)) -> 1.7743677 | G43: ='Macro-Economic_Demographic Data'!Y33/100 -> 0.235 | H43: =LN(G43/(1-G43)) -> -1.1802903
B46: PROJECTION 2025-2060
B47: Year | C47: GDP pc (2015 US$) | D47: Urban share | E47: Urban access (proj.) | F47: Rural access (proj.) | G47: National access (proj.) | J47: Caveats: The key judgment is the assumption Nigeria eventually undergoes the same transition its peers completed, which its stagnant 1995-2024 history alone would not predict. Survivorship applies: the analogue set contains only successful transitions. The rural path implies connection rates ~2-4 pp/yr through the 2030s-40s, far above Nigeria's historical pace. The 2003 national observation (52.2%) remains a retained survey outlier.
B48: ='Macro-Economic_Demographic Data'!A34 -> 2025 | C48: ='Macro-Economic_Demographic Data'!P34 -> 2393.1216 | D48: ='Macro-Economic_Demographic Data'!D34/100 -> 0.63775418 | E48: ='Macro-Economic_Demographic Data'!Z34/100 -> 0.87639894 | F48: ='Macro-Economic_Demographic Data'!Y34/100 -> 0.27635921 | G48: ='Macro-Economic_Demographic Data'!X34/100 -> 0.65903705
B49: ='Macro-Economic_Demographic Data'!A35 -> 2026 | C49: ='Macro-Economic_Demographic Data'!P35 -> 2461.6784 | D49: ='Macro-Economic_Demographic Data'!D35/100 -> 0.64574207 | E49: ='Macro-Economic_Demographic Data'!Z35/100 -> 0.89502757 | F49: ='Macro-Economic_Demographic Data'!Y35/100 -> 0.32193426 | G49: ='Macro-Economic_Demographic Data'!X35/100 -> 0.69200472
B50: ='Macro-Economic_Demographic Data'!A36 -> 2027 | C50: ='Macro-Economic_Demographic Data'!P36 -> 2532.7478 | D50: ='Macro-Economic_Demographic Data'!D36/100 -> 0.65371914 | E50: ='Macro-Economic_Demographic Data'!Z36/100 -> 0.91113326 | F50: ='Macro-Economic_Demographic Data'!Y36/100 -> 0.37117013 | G50: ='Macro-Economic_Demographic Data'!X36/100 -> 0.72415436
B51: ='Macro-Economic_Demographic Data'!A37 -> 2028 | C51: ='Macro-Economic_Demographic Data'!P37 -> 2606.6271 | D51: ='Macro-Economic_Demographic Data'!D37/100 -> 0.66168518 | E51: ='Macro-Economic_Demographic Data'!Z37/100 -> 0.92497503 | F51: ='Macro-Economic_Demographic Data'!Y37/100 -> 0.42323594 | G51: ='Macro-Economic_Demographic Data'!X37/100 -> 0.75522926 | S51: HISTORICAL-ANALOGUE (LEADER-FOLLOWER) DIFFUSION MODEL projection
...

Sheet Urban Panel
B2: Urban Access: Cross-Country Panel Calibration
B4: Method: urban access is regressed on ln(GDP per capita) across a 70-country developing-world cross-section (WDI 2020 vintage; matched-year observations; access capped at 99.5% for the logit; GDP pc <= $15,000; countries with mixed data years excluded; Nigeria excluded from estimation). Nigeria's country effect = its actual 2024 logit minus the panel prediction at its income. The projection lets that (negative) country effect decay with a documented half-life - benchmarked on Kenya's and Ghana's urban convergence episodes - toward a 99% ceiling (structural exclusion persists even in rich countries).
B13: Country | C13: Urban access 2020 (%) | D13: GDP pc 2020 (constant 2010 US$) | E13: Capped access (frac) | F13: Logit(access) | G13: ln(GDP pc) | J13: CALIBRATION
B14: Costa Rica | C14: 99.94 | D14: 12105.93 | E14: =MIN(C14/100,0.995) -> 0.995 | F14: =LN(E14/(1-E14)) -> 5.2933048 | G14: =LN(D14) -> 9.4014507 | J14: Panel slope on ln(GDP pc) | K14: =SLOPE(F14:F83,G14:G83) -> 1.1875277
B15: Algeria | C15: 99.88 | D15: 3834.44 | E15: =MIN(C15/100,0.995) -> 0.995 | F15: =LN(E15/(1-E15)) -> 5.2933048 | G15: =LN(D15) -> 8.2517787 | J15: Panel intercept | K15: =INTERCEPT(F14:F83,G14:G83) -> -6.3883541
B16: Bulgaria | C16: 99.8 | D16: 7920.91 | E16: =MIN(C16/100,0.995) -> 0.995 | F16: =LN(E16/(1-E16)) -> 5.2933048 | G16: =LN(D16) -> 8.9772614 | J16: Panel R-squared (logit space) | K16: =RSQ(F14:F83,G14:G83) -> 0.41212837
B17: Mexico | C17: 99.8 | D17: 8909.68 | E17: =MIN(C17/100,0.995) -> 0.995 | F17: =LN(E17/(1-E17)) -> 5.2933048 | G17: =LN(D17) -> 9.0948936 | J17: Nigeria 2020 GDP pc in panel units (2010$, WDI) | K17: 2396.04
B18: Comoros | C18: 99.72 | D18: 1255.04 | E18: =MIN(C18/100,0.995) -> 0.995 | F18: =LN(E18/(1-E18)) -> 5.2933048 | G18: =LN(D18) -> 7.1349227 | J18: Base-year bridge ratio (2015$ series / 2010$ series) | K18: ='Macro-Economic_Demographic Data'!P29/K17 -> 0.94006155
B19: Mongolia | C19: 99.7 | D19: 4126.7 | E19: =MIN(C19/100,0.995) -> 0.995 | F19: =LN(E19/(1-E19)) -> 5.2933048 | G19: =LN(D19) -> 8.3252333 | J19: Nigeria ln(GDP pc 2024, panel units) | K19: =LN('Macro-Economic_Demographic Data'!P33/K18) -> 7.8235163
B20: Panama | C20: 99.69 | D20: 12172.31 | E20: =MIN(C20/100,0.995) -> 0.995 | F20: =LN(E20/(1-E20)) -> 5.2933048 | G20: =LN(D20) -> 9.406919 | J20: Panel-predicted urban logit at Nigeria's 2024 income | K20: =K15+K14*K19 -> 2.9022885
B21: Ecuador | C21: 99.66 | D21: 5317.68 | E21: =MIN(C21/100,0.995) -> 0.995 | F21: =LN(E21/(1-E21)) -> 5.2933048 | G21: =LN(D21) -> 8.5787924 | J21: Nigeria actual urban logit 2024 (85.5%) | K21: =LN('Macro-Economic_Demographic Data'!Z33/100/(1-'Macro-Economic_Demographic Data'!Z33/100)) -> 1.7743677
B22: Indonesia | C22: 99.6 | D22: 3756.91 | E22: =MIN(C22/100,0.995) -> 0.995 | F22: =LN(E22/(1-E22)) -> 5.2933048 | G22: =LN(D22) -> 8.2313521 | J22: Nigeria country effect (residual, logit units) | K22: =K21-K20 -> -1.1279207
B23: Kyrgyz Republic | C23: 99.5 | D23: 1100.04 | E23: =MIN(C23/100,0.995) -> 0.995 | F23: =LN(E23/(1-E23)) -> 5.2933048 | G23: =LN(D23) -> 7.0031018 | J23: Convergence half-life of country effect (years) | K23: 12
B24: Afghanistan | C24: 99.5 | D24: 529.74 | E24: =MIN(C24/100,0.995) -> 0.995 | F24: =LN(E24/(1-E24)) -> 5.2933048 | G24: =LN(D24) -> 6.2723863 | J24: Urban access ceiling | K24: 0.99
B25: Mauritius | C25: 99.41 | D25: 9058.21 | E25: =MIN(C25/100,0.995) -> 0.9941 | F25: =LN(E25/(1-E25)) -> 5.1268855 | G25: =LN(D25) -> 9.1114268
B26: Tajikistan | C26: 99.05 | D26: 1199.06 | E26: =MIN(C26/100,0.995) -> 0.9905 | F26: =LN(E26/(1-E26)) -> 4.6469181 | G26: =LN(D26) -> 7.0892932 | J26: Half-life benchmark: Kenya's urban access rose from ~60% (2000) to 94% (2020) - the unserved gap halved roughly every 7-8 years; Ghana's episode implies ~10 years. 12 years is chosen as a deliberately conservative central value. Ceiling of 99% reflects persistent structural exclusion (informal settlements) observed even in upper-middle-income countries.
B27: Suriname | C27: 98.98 | D27: 7529.61 | E27: =MIN(C27/100,0.995) -> 0.9898 | F27: =LN(E27/(1-E27)) -> 4.5751152 | G27: =LN(D27) -> 8.9265985
B28: Gabon | C28: 98.59 | D28: 6818.5 | E28: =MIN(C28/100,0.995) -> 0.9859 | F28: =LN(E28/(1-E28)) -> 4.2473801 | G28: =LN(D28) -> 8.8273948
B29: Belize | C29: 98.33 | D29: 3968.49 | E29: =MIN(C29/100,0.995) -> 0.9833 | F29: =LN(E29/(1-E29)) -> 4.0755055 | G29: =LN(D29) -> 8.2861409
B30: Philippines | C30: 98.23 | D30: 3269.67 | E30: =MIN(C30/100,0.995) -> 0.9823 | F30: =LN(E30/(1-E30)) -> 4.0163321 | G30: =LN(D30) -> 8.0924443
B31: Bangladesh | C31: 97.8 | D31: 1643.67 | E31: =MIN(C31/100,0.995) -> 0.978 | F31: =LN(E31/(1-E31)) -> 3.7944672 | G31: =LN(D31) -> 7.4046868
B32: Guatemala | C32: 97.46 | D32: 4126.21 | E32: =MIN(C32/100,0.995) -> 0.9746 | F32: =LN(E32/(1-E32)) -> 3.647278 | G32: =LN(D32) -> 8.3251146
B33: Cambodia | C33: 97.3 | D33: 1376.41 | E33: =MIN(C33/100,0.995) -> 0.973 | F33: =LN(E33/(1-E33)) -> 3.5845472 | G33: =LN(D33) -> 7.2272339
B34: Guyana | C34: 96.9 | D34: 9250.3 | E34: =MIN(C34/100,0.995) -> 0.969 | F34: =LN(E34/(1-E34)) -> 3.4422774 | G34: =LN(D34) -> 9.1324113
B35: Vanuatu | C35: 95.59 | D35: 2638.89 | E35: =MIN(C35/100,0.995) -> 0.9559 | F35: =LN(E35/(1-E35)) -> 3.0761935 | G35: =LN(D35) -> 7.8781137
B36: Senegal | C36: 95.18 | D36: 1364.84 | E36: =MIN(C36/100,0.995) -> 0.9518 | F36: =LN(E36/(1-E36)) -> 2.9829959 | G36: =LN(D36) -> 7.2187925
B37: Ghana | C37: 94.71 | D37: 2018.62 | E37: =MIN(C37/100,0.995) -> 0.9471 | F37: =LN(E37/(1-E37)) -> 2.8850013 | G37: =LN(D37) -> 7.6101694
B38: Cabo Verde | C38: 94.49 | D38: 2935.32 | E38: =MIN(C38/100,0.995) -> 0.9449 | F38: =LN(E38/(1-E38)) -> 2.8419294 | G38: =LN(D38) -> 7.9845718
... B83: Central African Republic | C83: 33.56 | D83: 414.4 | E83: =MIN(C83/100,0.995) -> 0.3356 | F83: =LN(E83/(1-E83)) -> -0.6829644 | G83: =LN(D83) -> 6.0268317
B85: Source: World Bank WDI - EG.ELC.ACCS.UR.ZS and NY.GDP.PCAP.KD, 2020 values, retrieved via IndexMundi country rankings (https://www.indexmundi.com/facts/indicators/EG.ELC.ACCS.UR.ZS/rankings ; https://www.indexmundi.com/facts/indicators/NY.GDP.PCAP.KD/rankings). Nigeria's own 2020 row (83.90%, $2,396.04) is deliberately excluded from estimation and used only for the bridge ratio below.
